Workbook

Sheet CK
A1: Cohen's Kappa
C3: Judge 1 | M3: Judge 1 | S3: Judge 1
A4: Judge 2 | B4: A | C4: B | D4: C | E4: Total | K4: Judge 2 | L4: A | M4: B | N4: C | O4: Total | Q4: Judge 2 | R4: A | S4: B | T4: C | U4: Total
A5: A | B5: 10 | C5: 4 | D5: 1 | E5: =SUM(B5:D5) -> 15 | K5: A | L5: =B5/$E$8 -> 0.2 | M5: =C5/$E$8 -> 0.08 | N5: =D5/$E$8 -> 0.02 | O5: =SUM(L5:N5) -> 0.3 | Q5: A | R5: 0.32 | S5: 0 | T5: 0 | U5: =SUM(R5:T5) -> 0.32
A6: B | B6: 6 | C6: 16 | D6: 2 | E6: =SUM(B6:D6) -> 24 | K6: B | L6: =B6/$E$8 -> 0.12 | M6: =C6/$E$8 -> 0.32 | N6: =D6/$E$8 -> 0.04 | O6: =SUM(L6:N6) -> 0.48 | Q6: B | R6: 0 | S6: 0.46 | T6: 0 | U6: =SUM(R6:T6) -> 0.46
A7: C | B7: 0 | C7: 3 | D7: 8 | E7: =SUM(B7:D7) -> 11 | K7: C | L7: =B7/$E$8 -> 0 | M7: =C7/$E$8 -> 0.06 | N7: =D7/$E$8 -> 0.16 | O7: =SUM(L7:N7) -> 0.22 | Q7: C | R7: 0 | S7: 0 | T7: 0.22 | U7: =SUM(R7:T7) -> 0.22
A8: Total | B8: =SUM(B5:B7) -> 16 | C8: =SUM(C5:C7) -> 23 | D8: =SUM(D5:D7) -> 11 | E8: =SUM(B8:D8) -> 50 | K8: Total | L8: =SUM(L5:L7) -> 0.32 | M8: =SUM(M5:M7) -> 0.46 | N8: =SUM(N5:N7) -> 0.22 | O8: =SUM(L8:N8) -> 1 | Q8: Total | R8: =SUM(R5:R7) -> 0.32 | S8: =SUM(S5:S7) -> 0.46 | T8: =SUM(T5:T7) -> 0.22 | U8: =SUM(R8:T8) -> 1
A10: Agreement | B10: =B5 -> 10 | C10: =C6 -> 16 | D10: =D7 -> 8 | E10: =SUM(B10:D10) -> 34 | F10: na | K10: Agreement | L10: =L5 -> 0.2 | M10: =M6 -> 0.32 | N10: =N7 -> 0.16 | O10: =SUM(L10:N10) -> 0.68 | P10: pa | Q10: Agreement | R10: =R5 -> 0.32 | S10: =S6 -> 0.46 | T10: =T7 -> 0.22 | U10: =SUM(R10:T10) -> 1
A11: By Chance | B11: =B$8*$E5/$E$8 -> 4.8 | C11: =C$8*$E6/$E$8 -> 11.04 | D11: =D$8*$E7/$E$8 -> 2.42 | E11: =SUM(B11:D11) -> 18.26 | F11: ne | K11: By Chance | L11: =L$8*$O5/$O$8 -> 0.096 | M11: =M$8*$O6/$O$8 -> 0.2208 | N11: =N$8*$O7/$O$8 -> 0.0484 | O11: =SUM(L11:N11) -> 0.3652 | P11: pe | Q11: By Chance | R11: =R$8*$U5/$U$8 -> 0.1024 | S11: =S$8*$U6/$U$8 -> 0.2116 | T11: =T$8*$U7/$U$8 -> 0.0484 | U11: =SUM(R11:T11) -> 0.3624
A13: Kappa | B13: =(E10-E11)/(E8-E11) -> 0.49590422 | K13: Kappa | L13: =(O10-O11)/(O8-O11) -> 0.49590422 | Q13: Kappa | R13: =(U10-U11)/(U8-U11) -> 1

Sheet WK_3class
A3: Confusion Matrix | M3: Confusion Matrix
G4: Weighted Kappa (Linear) | S4: Unweighted Kappa (Cohen's Kappa)
C5: Judge 1 | I5: Weight | O5: Judge 1 | U5: Weight
A6: Judge 2 | B6: A | C6: B | D6: C | E6: Total | H6: A | I6: B | J6: C | M6: Judge 2 | N6: A | O6: B | P6: C | Q6: Total | T6: A | U6: B | V6: C
A7: A | B7: 16 | C7: 6 | D7: 2 | E7: =SUM(B7:D7) -> 24 | G7: A | H7: 0 | I7: 1 | J7: 2 | M7: A | N7: 16 | O7: 6 | P7: 2 | Q7: =SUM(N7:P7) -> 24 | S7: A | T7: 0 | U7: 1 | V7: 1
A8: B | B8: 4 | C8: 10 | D8: 1 | E8: =SUM(B8:D8) -> 15 | G8: B | H8: 1 | I8: 0 | J8: 1 | M8: B | N8: 4 | O8: 10 | P8: 1 | Q8: =SUM(N8:P8) -> 15 | S8: B | T8: 1 | U8: 0 | V8: 1
A9: C | B9: 3 | C9: 0 | D9: 8 | E9: =SUM(B9:D9) -> 11 | G9: C | H9: 2 | I9: 1 | J9: 0 | M9: C | N9: 3 | O9: 0 | P9: 8 | Q9: =SUM(N9:P9) -> 11 | S9: C | T9: 1 | U9: 1 | V9: 0
A10: Total | B10: =SUM(B7:B9) -> 23 | C10: =SUM(C7:C9) -> 16 | D10: =SUM(D7:D9) -> 11 | E10: =SUM(B10:D10) -> 50 | M10: Total | N10: =SUM(N7:N9) -> 23 | O10: =SUM(O7:O9) -> 16 | P10: =SUM(P7:P9) -> 11 | Q10: =SUM(N10:P10) -> 50
A12: Expected Matrix | M12: Expected Matrix
C14: Judge 1 | O14: Judge 1
A15: Judge 2 | B15: A | C15: B | D15: C | E15: Total | G15: Kappa | H15: =1-(K15/K16) -> 0.50095057 | J15: num: | K15: =SUMPRODUCT(B7:D9,H7:J9) -> 21 | M15: Judge 2 | N15: A | O15: B | P15: C | Q15: Total | S15: Kappa | T15: =1-(W15/W16) -> 0.49590422 | V15: num: | W15: =SUMPRODUCT(N7:P9,T7:V9) -> 16
A16: A | B16: =B$10*$E7/$E$10 -> 11.04 | C16: =C$10*$E7/$E$10 -> 7.68 | D16: =D$10*$E7/$E$10 -> 5.28 | E16: =SUM(B16:D16) -> 24 | J16: den: | K16: =SUMPRODUCT(B16:D18,H7:J9) -> 42.08 | M16: A | N16: =N$10*$E7/$E$10 -> 11.04 | O16: =O$10*$E7/$E$10 -> 7.68 | P16: =P$10*$E7/$E$10 -> 5.28 | Q16: =SUM(N16:P16) -> 24 | V16: den: | W16: =SUMPRODUCT(N16:P18,T7:V9) -> 31.74
A17: B | B17: =B$10*$E8/$E$10 -> 6.9 | C17: =C$10*$E8/$E$10 -> 4.8 | D17: =D$10*$E8/$E$10 -> 3.3 | E17: =SUM(B17:D17) -> 15 | M17: B | N17: =N$10*$E8/$E$10 -> 6.9 | O17: =O$10*$E8/$E$10 -> 4.8 | P17: =P$10*$E8/$E$10 -> 3.3 | Q17: =SUM(N17:P17) -> 15
A18: C | B18: =B$10*$E9/$E$10 -> 5.06 | C18: =C$10*$E9/$E$10 -> 3.52 | D18: =D$10*$E9/$E$10 -> 2.42 | E18: =SUM(B18:D18) -> 11 | J18: K: | K18: =1-(K15/K16) -> 0.50095057 | M18: C | N18: =N$10*$E9/$E$10 -> 5.06 | O18: =O$10*$E9/$E$10 -> 3.52 | P18: =P$10*$E9/$E$10 -> 2.42 | Q18: =SUM(N18:P18) -> 11 | V18: K: | W18: =1-(W15/W16) -> 0.49590422
A19: Total | B19: =SUM(B16:B18) -> 23 | C19: =SUM(C16:C18) -> 16 | D19: =SUM(D16:D18) -> 11 | E19: =SUM(B16:D18) -> 50 | M19: Total | N19: =SUM(N16:N18) -> 23 | O19: =SUM(O16:O18) -> 16 | P19: =SUM(P16:P18) -> 11 | Q19: =SUM(N19:P19) -> 50
G31: Weighted Kappa (Quadratic) | S31: Weighted Kappa (Quadratic)
C32: Judge 1 | I32: Weight | O32: Judge 1 | U32: Weight
A33: Judge 2 | B33: A | C33: B | D33: C | E33: Total | H33: A | I33: B | J33: C | M33: Judge 2 | N33: A | O33: B | P33: C | Q33: Total | T33: A | U33: B | V33: C
A34: A | B34: 16 | C34: 6 | D34: 2 | E34: =SUM(B34:D34) -> 24 | G34: A | H34: 0 | I34: 1 | J34: 4 | M34: A | N34: 16 | O34: 6 | P34: 2 | Q34: =SUM(N34:P34) -> 24 | S34: A | T34: 0 | U34: 0.25 | V34: 1
A35: B | B35: 4 | C35: 10 | D35: 1 | E35: =SUM(B35:D35) -> 15 | G35: B | H35: 1 | I35: 0 | J35: 1 | M35: B | N35: 4 | O35: 10 | P35: 1 | Q35: =SUM(N35:P35) -> 15 | S35: B | T35: 0.25 | U35: 0 | V35: 0.25
A36: C | B36: 3 | C36: 0 | D36: 8 | E36: =SUM(B36:D36) -> 11 | G36: C | H36: 4 | I36: 1 | J36: 0 | M36: C | N36: 3 | O36: 0 | P36: 8 | Q36: =SUM(N36:P36) -> 11 | S36: C | T36: 1 | U36: 0.25 | V36: 0
A37: Total | B37: =SUM(B34:B36) -> 23 | C37: =SUM(C34:C36) -> 16 | D37: =SUM(D34:D36) -> 11 | E37: =SUM(B37:D37) -> 50 | M37: Total | N37: =SUM(N34:N36) -> 23 | O37: =SUM(O34:O36) -> 16 | P37: =SUM(P34:P36) -> 11 | Q37: =SUM(N37:P37) -> 50
A39: Expectations | M39: Expectations
C41: Judge 1 | O41: Judge 1
A42: Judge 2 | B42: A | C42: B | D42: C | E42: Total | G42: Kappa | H42: =1-(J42/J43) -> 0.50605481 | J42: =SUMPRODUCT(B34:D36,H34:J36) -> 31 | M42: Judge 2 | N42: A | O42: B | P42: C | Q42: Total | S42: Kappa | T42: =1-(V42/V43) -> 0.50605481 | V42: =SUMPRODUCT(N34:P36,T34:V36) -> 7.75
A43: A | B43: =B$10*$E34/$E$10 -> 11.04 | C43: =C$10*$E34/$E$10 -> 7.68 | D43: =D$10*$E34/$E$10 -> 5.28 | E43: =SUM(B43:D43) -> 24 | J43: =SUMPRODUCT(B43:D45,H34:J36) -> 62.76 | M43: A | N43: =N$10*$E34/$E$10 -> 11.04 | O43: =O$10*$E34/$E$10 -> 7.68 | P43: =P$10*$E34/$E$10 -> 5.28 | Q43: =SUM(N43:P43) -> 24 | V43: =SUMPRODUCT(N43:P45,T34:V36) -> 15.69
A44: B | B44: =B$10*$E35/$E$10 -> 6.9 | C44: =C$10*$E35/$E$10 -> 4.8 | D44: =D$10*$E35/$E$10 -> 3.3 | E44: =SUM(B44:D44) -> 15 | M44: B | N44: =N$10*$E35/$E$10 -> 6.9 | O44: =O$10*$E35/$E$10 -> 4.8 | P44: =P$10*$E35/$E$10 -> 3.3 | Q44: =SUM(N44:P44) -> 15
A45: C | B45: =B$10*$E36/$E$10 -> 5.06 | C45: =C$10*$E36/$E$10 -> 3.52 | D45: =D$10*$E36/$E$10 -> 2.42 | E45: =SUM(B45:D45) -> 11 | M45: C | N45: =N$10*$E36/$E$10 -> 5.06 | O45: =O$10*$E36/$E$10 -> 3.52 | P45: =P$10*$E36/$E$10 -> 2.42 | Q45: =SUM(N45:P45) -> 11
A46: Total | B46: =SUM(B43:B45) -> 23 | C46: =SUM(C43:C45) -> 16 | D46: =SUM(D43:D45) -> 11 | E46: =SUM(B46:D46) -> 50 | M46: Total | N46: =SUM(N43:N45) -> 23 | O46: =SUM(O43:O45) -> 16 | P46: =SUM(P43:P45) -> 11 | Q46: =SUM(N46:P46) -> 50

Sheet Paradox_3class
B2: judge1
B3: judge2
G4: Weighted Kappa (Linear) | R4: Unweighted Kappa (Cohen's Kappa)
C5: Judge 1 | I5: Weight | N5: Judge 1 | T5: Weight
A6: Judge 2 | B6: A | C6: B | D6: C | E6: Total | H6: A | I6: B | J6: C | L6: Judge 2 | M6: A | N6: B | O6: C | P6: Total | S6: A | T6: B | U6: C
A7: A | B7: 30 | C7: 6 | D7: 2 | E7: =SUM(B7:D7) -> 38 | G7: A | H7: 0 | I7: 1 | J7: 2 | L7: A | M7: =B7 -> 30 | N7: =C7 -> 6 | O7: =D7 -> 2 | P7: =SUM(M7:O7) -> 38 | R7: A | S7: 0 | T7: 1 | U7: 1
A8: B | B8: 4 | C8: 2 | D8: 1 | E8: =SUM(B8:D8) -> 7 | G8: B | H8: 1 | I8: 0 | J8: 1 | L8: B | M8: =B8 -> 4 | N8: =C8 -> 2 | O8: =D8 -> 1 | P8: =SUM(M8:O8) -> 7 | R8: B | S8: 1 | T8: 0 | U8: 1
A9: C | B9: 3 | C9: 0 | D9: 2 | E9: =SUM(B9:D9) -> 5 | G9: C | H9: 2 | I9: 1 | J9: 0 | L9: C | M9: =B9 -> 3 | N9: =C9 -> 0 | O9: =D9 -> 2 | P9: =SUM(M9:O9) -> 5 | R9: C | S9: 1 | T9: 1 | U9: 0
A10: Total | B10: =SUM(B7:B9) -> 37 | C10: =SUM(C7:C9) -> 8 | D10: =SUM(D7:D9) -> 5 | E10: =SUM(B10:D10) -> 50 | L10: Total | M10: =SUM(M7:M9) -> 37 | N10: =SUM(N7:N9) -> 8 | O10: =SUM(O7:O9) -> 5 | P10: =SUM(M10:O10) -> 50
A12: Expectations | L12: Expectations
C14: Judge 1 | N14: Judge 1
A15: Judge 2 | B15: A | C15: B | D15: C | E15: Total | G15: Kappa | H15: =1-(J15/J16) -> 0.24351585 | J15: =SUMPRODUCT(B7:D9,H7:J9) -> 21 | L15: Judge 2 | M15: A | N15: B | O15: C | P15: Total | R15: Kappa | S15: =1-(U15/U16) -> 0.21026654 | U15: =SUMPRODUCT(M7:O9,S7:U9) -> 16
A16: A | B16: =B$10*$E7/$E$10 -> 28.12 | C16: =C$10*$E7/$E$10 -> 6.08 | D16: =D$10*$E7/$E$10 -> 3.8 | E16: =SUM(B16:D16) -> 38 | J16: =SUMPRODUCT(B16:D18,H7:J9) -> 27.76 | L16: A | M16: =M$10*$P7/$P$10 -> 28.12 | N16: =N$10*$P7/$P$10 -> 6.08 | O16: =O$10*$P7/$P$10 -> 3.8 | P16: =SUM(M16:O16) -> 38 | U16: =SUMPRODUCT(M16:O18,S7:U9) -> 20.26
A17: B | B17: =B$10*$E8/$E$10 -> 5.18 | C17: =C$10*$E8/$E$10 -> 1.12 | D17: =D$10*$E8/$E$10 -> 0.7 | E17: =SUM(B17:D17) -> 7 | L17: B | M17: =M$10*$P8/$P$10 -> 5.18 | N17: =N$10*$P8/$P$10 -> 1.12 | O17: =O$10*$P8/$P$10 -> 0.7 | P17: =SUM(M17:O17) -> 7
A18: C | B18: =B$10*$E9/$E$10 -> 3.7 | C18: =C$10*$E9/$E$10 -> 0.8 | D18: =D$10*$E9/$E$10 -> 0.5 | E18: =SUM(B18:D18) -> 5 | L18: C | M18: =M$10*$P9/$P$10 -> 3.7 | N18: =N$10*$P9/$P$10 -> 0.8 | O18: =O$10*$P9/$P$10 -> 0.5 | P18: =SUM(M18:O18) -> 5
A19: Total | B19: =SUM(B16:B18) -> 37 | C19: =SUM(C16:C18) -> 8 | D19: =SUM(D16:D18) -> 5 | E19: =SUM(B19:D19) -> 50 | L19: Total | M19: =SUM(M16:M18) -> 37 | N19: =SUM(N16:N18) -> 8 | O19: =SUM(O16:O18) -> 5 | P19: =SUM(M19:O19) -> 50
G31: Weighted Kappa (Quadratic) | R31: Weighted Kappa (Quadratic)
C32: Judge 1 | I32: Weight | N32: Judge 1 | T32: Weight
A33: Judge 2 | B33: A | C33: B | D33: C | E33: Total | H33: A | I33: B | J33: C | L33: Judge 2 | M33: A | N33: B | O33: C | P33: Total | S33: A | T33: B | U33: C
A34: A | B34: =B7 -> 30 | C34: =C7 -> 6 | D34: =D7 -> 2 | E34: =SUM(B34:D34) -> 38 | G34: A | H34: 0 | I34: 1 | J34: 4 | L34: A | M34: =B7 -> 30 | N34: =C7 -> 6 | O34: =D7 -> 2 | P34: =SUM(M34:O34) -> 38 | R34: A | S34: 0 | T34: 0.25 | U34: 1
A35: B | B35: =B8 -> 4 | C35: =C8 -> 2 | D35: =D8 -> 1 | E35: =SUM(B35:D35) -> 7 | G35: B | H35: 1 | I35: 0 | J35: 1 | L35: B | M35: =B8 -> 4 | N35: =C8 -> 2 | O35: =D8 -> 1 | P35: =SUM(M35:O35) -> 7 | R35: B | S35: 0.25 | T35: 0 | U35: 0.25
A36: C | B36: =B9 -> 3 | C36: =C9 -> 0 | D36: =D9 -> 2 | E36: =SUM(B36:D36) -> 5 | G36: C | H36: 4 | I36: 1 | J36: 0 | L36: C | M36: =B9 -> 3 | N36: =C9 -> 0 | O36: =D9 -> 2 | P36: =SUM(M36:O36) -> 5 | R36: C | S36: 1 | T36: 0.25 | U36: 0
A37: Total | B37: =SUM(B34:B36) -> 37 | C37: =SUM(C34:C36) -> 8 | D37: =SUM(D34:D36) -> 5 | E37: =SUM(B37:D37) -> 50 | L37: Total | M37: =SUM(M34:M36) -> 37 | N37: =SUM(N34:N36) -> 8 | O37: =SUM(O34:O36) -> 5 | P37: =SUM(M37:O37) -> 50
A39: Expectations | L39: Expectations
C41: Judge 1 | N41: Judge 1
A42: Judge 2 | B42: A | C42: B | D42: C | E42: Total | G42: Kappa | H42: =1-(J42/J43) -> 0.27502339 | J42: =SUMPRODUCT(B34:D36,H34:J36) -> 31 | L42: Judge 2 | M42: A | N42: B | O42: C | P42: Total | R42: Kappa | S42: =1-(U42/U43) -> 0.27502339 | U42: =SUMPRODUCT(M34:O36,S34:U36) -> 7.75
A43: A | B43: =B$10*$E34/$E$10 -> 28.12 | C43: =C$10*$E34/$E$10 -> 6.08 | D43: =D$10*$E34/$E$10 -> 3.8 | E43: =SUM(B43:D43) -> 38 | J43: =SUMPRODUCT(B43:D45,H34:J36) -> 42.76 | L43: A | M43: =M$10*$P34/$P$10 -> 28.12 | N43: =N$10*$P34/$P$10 -> 6.08 | O43: =O$10*$P34/$P$10 -> 3.8 | P43: =SUM(M43:O43) -> 38 | U43: =SUMPRODUCT(M43:O45,S34:U36) -> 10.69
A44: B | B44: =B$10*$E35/$E$10 -> 5.18 | C44: =C$10*$E35/$E$10 -> 1.12 | D44: =D$10*$E35/$E$10 -> 0.7 | E44: =SUM(B44:D44) -> 7 | L44: B | M44: =M$10*$P35/$P$10 -> 5.18 | N44: =N$10*$P35/$P$10 -> 1.12 | O44: =O$10*$P35/$P$10 -> 0.7 | P44: =SUM(M44:O44) -> 7
A45: C | B45: =B$10*$E36/$E$10 -> 3.7 | C45: =C$10*$E36/$E$10 -> 0.8 | D45: =D$10*$E36/$E$10 -> 0.5 | E45: =SUM(B45:D45) -> 5 | L45: C | M45: =M$10*$P36/$P$10 -> 3.7 | N45: =N$10*$P36/$P$10 -> 0.8 | O45: =O$10*$P36/$P$10 -> 0.5 | P45: =SUM(M45:O45) -> 5 | T45: k | U45: =1-(U42/U43) -> 0.27502339
A46: Total | B46: =SUM(B43:B45) -> 37 | C46: =SUM(C43:C45) -> 8 | D46: =SUM(D43:D45) -> 5 | E46: =SUM(B46:D46) -> 50 | L46: Total | M46: =SUM(M43:M45) -> 37 | N46: =SUM(N43:N45) -> 8 | O46: =SUM(O43:O45) -> 5 | P46: =SUM(M46:O46) -> 50

Sheet WK_4class
A3: Confusion Matrix | N3: Confusion Matrix
H4: Weighted Kappa (Linear) | U4: Unweighted Kappa (Cohen's Kappa)
C5: Judge 1 | J5: Weight | P5: Judge 1 | W5: Weight
A6: Judge 2 | B6: A | C6: B | D6: C | E6: D | F6: Total | I6: A | J6: B | K6: C | L6: D | N6: Judge 2 | O6: A | P6: B | Q6: C | R6: D | S6: Total | V6: A | W6: B | X6: C | Y6: D
A7: A | B7: 9 | C7: 4 | D7: 2 | E7: 1 | F7: =SUM(B7:E7) -> 16 | H7: A | I7: 0 | J7: 1 | K7: 2 | L7: 3 | N7: A | O7: =B7 -> 9 | P7: =C7 -> 4 | Q7: =D7 -> 2 | R7: =E7 -> 1 | S7: =SUM(O7:R7) -> 16 | U7: A | V7: 0 | W7: 1 | X7: 1 | Y7: 1
A8: B | B8: 4 | C8: 6 | D8: 1 | E8: 2 | F8: =SUM(B8:E8) -> 13 | H8: B | I8: 1 | J8: 0 | K8: 1 | L8: 2 | N8: B | O8: =B8 -> 4 | P8: =C8 -> 6 | Q8: =D8 -> 1 | R8: =E8 -> 2 | S8: =SUM(O8:R8) -> 13 | U8: B | V8: 1 | W8: 0 | X8: 1 | Y8: 1
A9: C | B9: 3 | C9: 0 | D9: 8 | E9: 0 | F9: =SUM(B9:E9) -> 11 | H9: C | I9: 2 | J9: 1 | K9: 0 | L9: 1 | N9: C | O9: =B9 -> 3 | P9: =C9 -> 0 | Q9: =D9 -> 8 | R9: =E9 -> 0 | S9: =SUM(O9:R9) -> 11 | U9: C | V9: 1 | W9: 1 | X9: 0 | Y9: 1
A10: D | B10: 1 | C10: 2 | D10: 0 | E10: 7 | F10: =SUM(B10:E10) -> 10 | H10: D | I10: 3 | J10: 2 | K10: 1 | L10: 0 | N10: D | O10: =B10 -> 1 | P10: =C10 -> 2 | Q10: =D10 -> 0 | R10: =E10 -> 7 | S10: =SUM(O10:R10) -> 10 | U10: D | V10: 1 | W10: 1 | X10: 1 | Y10: 0
A11: Total | B11: =SUM(B7:B10) -> 17 | C11: =SUM(C7:C10) -> 12 | D11: =SUM(D7:D10) -> 11 | E11: =SUM(E7:E10) -> 10 | F11: =SUM(B11:E11) -> 50 | N11: Total | O11: =SUM(O7:O10) -> 17 | P11: =SUM(P7:P10) -> 12 | Q11: =SUM(Q7:Q10) -> 11 | R11: =SUM(R7:R10) -> 10 | S11: =SUM(O11:R11) -> 50
A13: Expected Matrix | N13: Expected Matrix
C15: Judge 1 | P15: Judge 1
A16: Judge 2 | B16: A | C16: B | D16: C | E16: D | F16: Total | H16: Kappa | I16: =1-(L16/L17) -> 0.47183099 | K16: num: | L16: =SUMPRODUCT(B7:E10,I7:L10) -> 33 | N16: Judge 2 | O16: A | P16: B | Q16: C | R16: D | S16: Total | U16: Kappa | V16: =1-(Y16/Y17) -> 0.45975149 | X16: num: | Y16: =SUMPRODUCT(O7:R10,V7:Y10) -> 20
A17: A | B17: =B$11*$F7/$F$11 -> 5.44 | C17: =C$11*$F7/$F$11 -> 3.84 | D17: =D$11*$F7/$F$11 -> 3.52 | E17: =E$11*$F7/$F$11 -> 3.2 | F17: =SUM(B17:E17) -> 16 | K17: den: | L17: =SUMPRODUCT(B17:E20,I7:L10) -> 62.48 | N17: A | O17: =O$11*$F7/$F$11 -> 5.44 | P17: =P$11*$F7/$F$11 -> 3.84 | Q17: =Q$11*$F7/$F$11 -> 3.52 | R17: =R$11*$F7/$F$11 -> 3.2 | S17: =SUM(O17:R17) -> 16 | X17: den: | Y17: =SUMPRODUCT(O17:R20,V7:Y10) -> 37.02
A18: B | B18: =B$11*$F8/$F$11 -> 4.42 | C18: =C$11*$F8/$F$11 -> 3.12 | D18: =D$11*$F8/$F$11 -> 2.86 | E18: =E$11*$F8/$F$11 -> 2.6 | F18: =SUM(B18:E18) -> 13 | N18: B | O18: =O$11*$F8/$F$11 -> 4.42 | P18: =P$11*$F8/$F$11 -> 3.12 | Q18: =Q$11*$F8/$F$11 -> 2.86 | R18: =R$11*$F8/$F$11 -> 2.6 | S18: =SUM(O18:R18) -> 13
A19: C | B19: =B$11*$F9/$F$11 -> 3.74 | C19: =C$11*$F9/$F$11 -> 2.64 | D19: =D$11*$F9/$F$11 -> 2.42 | E19: =E$11*$F9/$F$11 -> 2.2 | F19: =SUM(B19:E19) -> 11 | K19: K: | L19: =1-(L16/L17) -> 0.47183099 | N19: C | O19: =O$11*$F9/$F$11 -> 3.74 | P19: =P$11*$F9/$F$11 -> 2.64 | Q19: =Q$11*$F9/$F$11 -> 2.42 | R19: =R$11*$F9/$F$11 -> 2.2 | S19: =SUM(O19:R19) -> 11 | X19: K: | Y19: =1-(Y16/Y17) -> 0.45975149
A20: D | B20: =B$11*$F10/$F$11 -> 3.4 | C20: =C$11*$F10/$F$11 -> 2.4 | D20: =D$11*$F10/$F$11 -> 2.2 | E20: =E$11*$F10/$F$11 -> 2 | F20: =SUM(B20:E20) -> 10 | N20: D | O20: =O$11*$F10/$F$11 -> 3.4 | P20: =P$11*$F10/$F$11 -> 2.4 | Q20: =Q$11*$F10/$F$11 -> 2.2 | R20: =R$11*$F10/$F$11 -> 2 | S20: =SUM(O20:R20) -> 10
A21: Total | B21: =SUM(B17:B20) -> 17 | C21: =SUM(C17:C20) -> 12 | D21: =SUM(D17:D20) -> 11 | E21: =SUM(E17:E20) -> 10 | F21: =SUM(B17:E20) -> 50 | N21: Total | O21: =SUM(O17:O20) -> 17 | P21: =SUM(P17:P20) -> 12 | Q21: =SUM(Q17:Q20) -> 11 | R21: =SUM(R17:R20) -> 10 | S21: =SUM(O21:R21) -> 50
A30: Confusion Matrix
H31: Weighted Kappa (Quadratic)
C32: Judge 1 | J32: Weight
A33: Judge 2 | B33: A | C33: B | D33: C | E33: D | F33: Total | I33: A | J33: B | K33: C | L33: D
A34: A | B34: =B7 -> 9 | C34: =C7 -> 4 | D34: =D7 -> 2 | E34: =E7 -> 1 | F34: =SUM(B34:E34) -> 16 | H34: A | I34: 0 | J34: 0.1111 | K34: 0.4444 | L34: 1
A35: B | B35: =B8 -> 4 | C35: =C8 -> 6 | D35: =D8 -> 1 | E35: =E8 -> 2 | F35: =SUM(B35:E35) -> 13 | H35: B | I35: 0.1111 | J35: 0 | K35: 0.1111 | L35: 0.4444
A36: C | B36: =B9 -> 3 | C36: =C9 -> 0 | D36: =D9 -> 8 | E36: =E9 -> 0 | F36: =SUM(B36:E36) -> 11 | H36: C | I36: 0.4444 | J36: 0.1111 | K36: 0 | L36: 0.1111
A37: D | B37: =B10 -> 1 | C37: =C10 -> 2 | D37: =D10 -> 0 | E37: =E10 -> 7 | F37: =SUM(B37:E37) -> 10 | H37: D | I37: 1 | J37: 0.4444 | K37: 0.1111 | L37: 0
A38: Total | B38: =SUM(B34:B37) -> 17 | C38: =SUM(C34:C37) -> 12 | D38: =SUM(D34:D37) -> 11 | E38: =SUM(E34:E37) -> 10 | F38: =SUM(B38:E38) -> 50
A40: Expected Matrix
C42: Judge 1
A43: Judge 2 | B43: A | C43: B | D43: C | E43: D | F43: Total | H43: Kappa | I43: =1-(K43/K44) -> 0.5023788 | J43: Num: | K43: =SUMPRODUCT(B34:E37,I34:L37) -> 6.9995
A44: A | B44: =B$11*$F34/$F$11 -> 5.44 | C44: =C$11*$F34/$F$11 -> 3.84 | D44: =D$11*$F34/$F$11 -> 3.52 | E44: =E$11*$F34/$F$11 -> 3.2 | F44: =SUM(B44:E44) -> 16 | J44: Den: | K44: =SUMPRODUCT(B44:E47,I34:L37) -> 14.06592
A45: B | B45: =B$11*$F35/$F$11 -> 4.42 | C45: =C$11*$F35/$F$11 -> 3.12 | D45: =D$11*$F35/$F$11 -> 2.86 | E45: =E$11*$F35/$F$11 -> 2.6 | F45: =SUM(B45:E45) -> 13
A46: C | B46: =B$11*$F36/$F$11 -> 3.74 | C46: =C$11*$F36/$F$11 -> 2.64 | D46: =D$11*$F36/$F$11 -> 2.42 | E46: =E$11*$F36/$F$11 -> 2.2 | F46: =SUM(B46:E46) -> 11
A47: D | B47: =B$11*$F37/$F$11 -> 3.4 | C47: =C$11*$F37/$F$11 -> 2.4 | D47: =D$11*$F37/$F$11 -> 2.2 | E47: =E$11*$F37/$F$11 -> 2 | F47: =SUM(B47:E47) -> 10
A48: Total | B48: =SUM(B44:B47) -> 17 | C48: =SUM(C44:C47) -> 12 | D48: =SUM(D44:D47) -> 11 | E48: =SUM(E44:E47) -> 10 | F48: =SUM(B48:E48) -> 50

Sheet Paradox_4class
A3: Confusion Matrix | N3: Confusion Matrix
H4: Weighted Kappa (Linear) | U4: Unweighted Kappa (Cohen's Kappa)
C5: Judge 1 | J5: Weight | P5: Judge 1 | W5: Weight
A6: Judge 2 | B6: A | C6: B | D6: C | E6: D | F6: Total | I6: A | J6: B | K6: C | L6: D | N6: Judge 2 | O6: A | P6: B | Q6: C | R6: D | S6: Total | V6: A | W6: B | X6: C | Y6: D
A7: A | B7: 20 | C7: 4 | D7: 2 | E7: 1 | F7: =SUM(B7:E7) -> 27 | H7: A | I7: 0 | J7: 1 | K7: 2 | L7: 3 | N7: A | O7: =B7 -> 20 | P7: =C7 -> 4 | Q7: =D7 -> 2 | R7: =E7 -> 1 | S7: =SUM(O7:R7) -> 27 | U7: A | V7: 0 | W7: 1 | X7: 1 | Y7: 1
A8: B | B8: 4 | C8: 3 | D8: 1 | E8: 2 | F8: =SUM(B8:E8) -> 10 | H8: B | I8: 1 | J8: 0 | K8: 1 | L8: 2 | N8: B | O8: =B8 -> 4 | P8: =C8 -> 3 | Q8: =D8 -> 1 | R8: =E8 -> 2 | S8: =SUM(O8:R8) -> 10 | U8: B | V8: 1 | W8: 0 | X8: 1 | Y8: 1
A9: C | B9: 3 | C9: 0 | D9: 2 | E9: 0 | F9: =SUM(B9:E9) -> 5 | H9: C | I9: 2 | J9: 1 | K9: 0 | L9: 1 | N9: C | O9: =B9 -> 3 | P9: =C9 -> 0 | Q9: =D9 -> 2 | R9: =E9 -> 0 | S9: =SUM(O9:R9) -> 5 | U9: C | V9: 1 | W9: 1 | X9: 0 | Y9: 1
A10: D | B10: 1 | C10: 2 | D10: 0 | E10: 5 | F10: =SUM(B10:E10) -> 8 | H10: D | I10: 3 | J10: 2 | K10: 1 | L10: 0 | N10: D | O10: =B10 -> 1 | P10: =C10 -> 2 | Q10: =D10 -> 0 | R10: =E10 -> 5 | S10: =SUM(O10:R10) -> 8 | U10: D | V10: 1 | W10: 1 | X10: 1 | Y10: 0
A11: Total | B11: =SUM(B7:B10) -> 28 | C11: =SUM(C7:C10) -> 9 | D11: =SUM(D7:D10) -> 5 | E11: =SUM(E7:E10) -> 8 | F11: =SUM(B11:E11) -> 50 | N11: Total | O11: =SUM(O7:O10) -> 28 | P11: =SUM(P7:P10) -> 9 | Q11: =SUM(Q7:Q10) -> 5 | R11: =SUM(R7:R10) -> 8 | S11: =SUM(O11:R11) -> 50
A13: Expected Matrix | N13: Expected Matrix
C15: Judge 1 | P15: Judge 1
A16: Judge 2 | B16: A | C16: B | D16: C | E16: D | F16: Total | H16: Kappa | I16: =1-(L16/L17) -> 0.42548747 | K16: num: | L16: =SUMPRODUCT(B7:E10,I7:L10) -> 33 | N16: Judge 2 | O16: A | P16: B | Q16: C | R16: D | S16: Total | U16: Kappa | V16: =1-(Y16/Y17) -> 0.36102236 | X16: num: | Y16: =SUMPRODUCT(O7:R10,V7:Y10) -> 20
A17: A | B17: =B$11*$F7/$F$11 -> 15.12 | C17: =C$11*$F7/$F$11 -> 4.86 | D17: =D$11*$F7/$F$11 -> 2.7 | E17: =E$11*$F7/$F$11 -> 4.32 | F17: =SUM(B17:E17) -> 27 | K17: den: | L17: =SUMPRODUCT(B17:E20,I7:L10) -> 57.44 | N17: A | O17: =O$11*$F7/$F$11 -> 15.12 | P17: =P$11*$F7/$F$11 -> 4.86 | Q17: =Q$11*$F7/$F$11 -> 2.7 | R17: =R$11*$F7/$F$11 -> 4.32 | S17: =SUM(O17:R17) -> 27 | X17: den: | Y17: =SUMPRODUCT(O17:R20,V7:Y10) -> 31.3
A18: B | B18: =B$11*$F8/$F$11 -> 5.6 | C18: =C$11*$F8/$F$11 -> 1.8 | D18: =D$11*$F8/$F$11 -> 1 | E18: =E$11*$F8/$F$11 -> 1.6 | F18: =SUM(B18:E18) -> 10 | N18: B | O18: =O$11*$F8/$F$11 -> 5.6 | P18: =P$11*$F8/$F$11 -> 1.8 | Q18: =Q$11*$F8/$F$11 -> 1 | R18: =R$11*$F8/$F$11 -> 1.6 | S18: =SUM(O18:R18) -> 10
A19: C | B19: =B$11*$F9/$F$11 -> 2.8 | C19: =C$11*$F9/$F$11 -> 0.9 | D19: =D$11*$F9/$F$11 -> 0.5 | E19: =E$11*$F9/$F$11 -> 0.8 | F19: =SUM(B19:E19) -> 5 | K19: K: | L19: =1-(L16/L17) -> 0.42548747 | N19: C | O19: =O$11*$F9/$F$11 -> 2.8 | P19: =P$11*$F9/$F$11 -> 0.9 | Q19: =Q$11*$F9/$F$11 -> 0.5 | R19: =R$11*$F9/$F$11 -> 0.8 | S19: =SUM(O19:R19) -> 5 | X19: K: | Y19: =1-(Y16/Y17) -> 0.36102236
A20: D | B20: =B$11*$F10/$F$11 -> 4.48 | C20: =C$11*$F10/$F$11 -> 1.44 | D20: =D$11*$F10/$F$11 -> 0.8 | E20: =E$11*$F10/$F$11 -> 1.28 | F20: =SUM(B20:E20) -> 8 | N20: D | O20: =O$11*$F10/$F$11 -> 4.48 | P20: =P$11*$F10/$F$11 -> 1.44 | Q20: =Q$11*$F10/$F$11 -> 0.8 | R20: =R$11*$F10/$F$11 -> 1.28 | S20: =SUM(O20:R20) -> 8
A21: Total | B21: =SUM(B17:B20) -> 28 | C21: =SUM(C17:C20) -> 9 | D21: =SUM(D17:D20) -> 5 | E21: =SUM(E17:E20) -> 8 | F21: =SUM(B17:E20) -> 50 | N21: Total | O21: =SUM(O17:O20) -> 28 | P21: =SUM(P17:P20) -> 9 | Q21: =SUM(Q17:Q20) -> 5 | R21: =SUM(R17:R20) -> 8 | S21: =SUM(O21:R21) -> 50
A30: Confusion Matrix
H31: Weighted Kappa (Quadratic)
C32: Judge 1 | J32: Weight
A33: Judge 2 | B33: A | C33: B | D33: C | E33: D | F33: Total | I33: A | J33: B | K33: C | L33: D
A34: A | B34: =B7 -> 20 | C34: =C7 -> 4 | D34: =D7 -> 2 | E34: =E7 -> 1 | F34: =SUM(B34:E34) -> 27 | H34: A | I34: 0 | J34: 0.1111 | K34: 0.4444 | L34: 1
A35: B | B35: =B8 -> 4 | C35: =C8 -> 3 | D35: =D8 -> 1 | E35: =E8 -> 2 | F35: =SUM(B35:E35) -> 10 | H35: B | I35: 0.1111 | J35: 0 | K35: 0.1111 | L35: 0.4444
A36: C | B36: =B9 -> 3 | C36: =C9 -> 0 | D36: =D9 -> 2 | E36: =E9 -> 0 | F36: =SUM(B36:E36) -> 5 | H36: C | I36: 0.4444 | J36: 0.1111 | K36: 0 | L36: 0.1111
A37: D | B37: =B10 -> 1 | C37: =C10 -> 2 | D37: =D10 -> 0 | E37: =E10 -> 5 | F37: =SUM(B37:E37) -> 8 | H37: D | I37: 1 | J37: 0.4444 | K37: 0.1111 | L37: 0
A38: Total | B38: =SUM(B34:B37) -> 28 | C38: =SUM(C34:C37) -> 9 | D38: =SUM(D34:D37) -> 5 | E38: =SUM(E34:E37) -> 8 | F38: =SUM(B38:E38) -> 50
A40: Expected Matrix
C42: Judge 1
A43: Judge 2 | B43: A | C43: B | D43: C | E43: D | F43: Total | H43: Kappa | I43: =1-(K43/K44) -> 0.50520043 | J43: Num: | K43: =SUMPRODUCT(B34:E37,I34:L37) -> 6.9995
A44: A | B44: =B$11*$F34/$F$11 -> 15.12 | C44: =C$11*$F34/$F$11 -> 4.86 | D44: =D$11*$F34/$F$11 -> 2.7 | E44: =E$11*$F34/$F$11 -> 4.32 | F44: =SUM(B44:E44) -> 27 | J44: Den: | K44: =SUMPRODUCT(B44:E47,I34:L37) -> 14.146132
A45: B | B45: =B$11*$F35/$F$11 -> 5.6 | C45: =C$11*$F35/$F$11 -> 1.8 | D45: =D$11*$F35/$F$11 -> 1 | E45: =E$11*$F35/$F$11 -> 1.6 | F45: =SUM(B45:E45) -> 10
A46: C | B46: =B$11*$F36/$F$11 -> 2.8 | C46: =C$11*$F36/$F$11 -> 0.9 | D46: =D$11*$F36/$F$11 -> 0.5 | E46: =E$11*$F36/$F$11 -> 0.8 | F46: =SUM(B46:E46) -> 5
A47: D | B47: =B$11*$F37/$F$11 -> 4.48 | C47: =C$11*$F37/$F$11 -> 1.44 | D47: =D$11*$F37/$F$11 -> 0.8 | E47: =E$11*$F37/$F$11 -> 1.28 | F47: =SUM(B47:E47) -> 8
A48: Total | B48: =SUM(B44:B47) -> 28 | C48: =SUM(C44:C47) -> 9 | D48: =SUM(D44:D47) -> 5 | E48: =SUM(E44:E47) -> 8 | F48: =SUM(B48:E48) -> 50

Sheet WK_5class
A3: Confusion Matrix | P3: Confusion Matrix
I4: Weighted Kappa (Linear) | X4: Unweighted Kappa (Cohen's Kappa)
C5: Judge 1 | K5: Weight | R5: Judge 1 | Z5: Weight
A6: Judge 2 | B6: A | C6: B | D6: C | E6: D | F6: E | G6: Total | J6: A | K6: B | L6: C | M6: D | N6: E | P6: Judge 2 | Q6: A | R6: B | S6: C | T6: D | U6: E | V6: Total | Y6: A | Z6: B | AA6: C | AB6: D | AC6: E
A7: A | B7: 7 | C7: 3 | D7: 2 | E7: 1 | F7: 0 | G7: =SUM(B7:F7) -> 13 | I7: A | J7: 0 | K7: 1 | L7: 2 | M7: 3 | N7: 4 | P7: A | Q7: =B7 -> 7 | R7: =C7 -> 3 | S7: =D7 -> 2 | T7: =E7 -> 1 | U7: =F7 -> 0 | V7: =SUM(Q7:T7) -> 13 | X7: A | Y7: 0 | Z7: 1 | AA7: 1 | AB7: 1 | AC7: 1
A8: B | B8: 2 | C8: 6 | D8: 1 | E8: 2 | F8: 1 | G8: =SUM(B8:F8) -> 12 | I8: B | J8: 1 | K8: 0 | L8: 1 | M8: 2 | N8: 3 | P8: B | Q8: =B8 -> 2 | R8: =C8 -> 6 | S8: =D8 -> 1 | T8: =E8 -> 2 | U8: =F8 -> 1 | V8: =SUM(Q8:T8) -> 11 | X8: B | Y8: 1 | Z8: 0 | AA8: 1 | AB8: 1 | AC8: 1
A9: C | B9: 2 | C9: 0 | D9: 7 | E9: 0 | F9: 1 | G9: =SUM(B9:F9) -> 10 | I9: C | J9: 2 | K9: 1 | L9: 0 | M9: 1 | N9: 2 | P9: C | Q9: =B9 -> 2 | R9: =C9 -> 0 | S9: =D9 -> 7 | T9: =E9 -> 0 | U9: =F9 -> 1 | V9: =SUM(Q9:T9) -> 9 | X9: C | Y9: 1 | Z9: 1 | AA9: 0 | AB9: 1 | AC9: 1
A10: D | B10: 1 | C10: 1 | D10: 0 | E10: 5 | F10: 0 | G10: =SUM(B10:F10) -> 7 | I10: D | J10: 3 | K10: 2 | L10: 1 | M10: 0 | N10: 1 | P10: D | Q10: =B10 -> 1 | R10: =C10 -> 1 | S10: =D10 -> 0 | T10: =E10 -> 5 | U10: =F10 -> 0 | V10: =SUM(Q10:T10) -> 7 | X10: D | Y10: 1 | Z10: 1 | AA10: 1 | AB10: 0 | AC10: 1
A11: E | B11: 0 | C11: 0 | D11: 2 | E11: 1 | F11: 5 | G11: =SUM(B11:F11) -> 8 | I11: E | J11: 4 | K11: 3 | L11: 2 | M11: 1 | N11: 0 | P11: E | Q11: =B11 -> 0 | R11: =C11 -> 0 | S11: =D11 -> 2 | T11: =E11 -> 1 | U11: =F11 -> 5 | V11: =SUM(Q11:T11) -> 3 | X11: E | Y11: 1 | Z11: 1 | AA11: 1 | AB11: 1 | AC11: 0
A12: Total | B12: =SUM(B7:B11) -> 12 | C12: =SUM(C7:C11) -> 10 | D12: =SUM(D7:D11) -> 12 | E12: =SUM(E7:E11) -> 9 | F12: =SUM(F7:F11) -> 7 | G12: =SUM(B7:F11) -> 50 | P12: Total | Q12: =SUM(Q7:Q11) -> 12 | R12: =SUM(R7:R11) -> 10 | S12: =SUM(S7:S11) -> 12 | T12: =SUM(T7:T11) -> 9 | U12: =SUM(U7:U11) -> 7 | V12: =SUM(Q7:U11) -> 50
A14: Expected Matrix | P14: Expected Matrix
C16: Judge 1 | R16: Judge 1
A17: Judge 2 | B17: A | C17: B | D17: C | E17: D | F17: E | G17: Total | I17: Kappa | J17: =1-(M17/M18) -> 0.53798768 | L17: num: | M17: =SUMPRODUCT(B7:F11,J7:N11) -> 36 | P17: Judge 2 | Q17: A | R17: B | S17: C | T17: D | U17: E | V17: Total | X17: Kappa | Y17: =1-(AB17/AB18) -> 0.49622166 | AA17: num: | AB17: =SUMPRODUCT(Q7:U11,Y7:AC11) -> 20
A18: A | B18: =B$12*$G7/$G$12 -> 3.12 | C18: =C$12*$G7/$G$12 -> 2.6 | D18: =D$12*$G7/$G$12 -> 3.12 | E18: =E$12*$G7/$G$12 -> 2.34 | F18: =F$12*$G7/$G$12 -> 1.82 | G18: =SUM(B18:F18) -> 13 | L18: den: | M18: =SUMPRODUCT(B18:F22,J7:N11) -> 77.92 | P18: A | Q18: =Q$12*$G7/$G$12 -> 3.12 | R18: =R$12*$G7/$G$12 -> 2.6 | S18: =S$12*$G7/$G$12 -> 3.12 | T18: =T$12*$G7/$G$12 -> 2.34 | U18: =U$12*$G7/$G$12 -> 1.82 | V18: =SUM(Q18:U18) -> 13 | AA18: den: | AB18: =SUMPRODUCT(Q18:U22,Y7:AC11) -> 39.7
A19: B | B19: =B$12*$G8/$G$12 -> 2.88 | C19: =C$12*$G8/$G$12 -> 2.4 | D19: =D$12*$G8/$G$12 -> 2.88 | E19: =E$12*$G8/$G$12 -> 2.16 | F19: =F$12*$G8/$G$12 -> 1.68 | G19: =SUM(B19:F19) -> 12 | P19: B | Q19: =Q$12*$G8/$G$12 -> 2.88 | R19: =R$12*$G8/$G$12 -> 2.4 | S19: =S$12*$G8/$G$12 -> 2.88 | T19: =T$12*$G8/$G$12 -> 2.16 | U19: =U$12*$G8/$G$12 -> 1.68 | V19: =SUM(Q19:U19) -> 12
A20: C | B20: =B$12*$G9/$G$12 -> 2.4 | C20: =C$12*$G9/$G$12 -> 2 | D20: =D$12*$G9/$G$12 -> 2.4 | E20: =E$12*$G9/$G$12 -> 1.8 | F20: =F$12*$G9/$G$12 -> 1.4 | G20: =SUM(B20:F20) -> 10 | L20: K: | M20: =1-(M17/M18) -> 0.53798768 | P20: C | Q20: =Q$12*$G9/$G$12 -> 2.4 | R20: =R$12*$G9/$G$12 -> 2 | S20: =S$12*$G9/$G$12 -> 2.4 | T20: =T$12*$G9/$G$12 -> 1.8 | U20: =U$12*$G9/$G$12 -> 1.4 | V20: =SUM(Q20:U20) -> 10 | AA20: K: | AB20: =1-(AB17/AB18) -> 0.49622166
A21: D | B21: =B$12*$G10/$G$12 -> 1.68 | C21: =C$12*$G10/$G$12 -> 1.4 | D21: =D$12*$G10/$G$12 -> 1.68 | E21: =E$12*$G10/$G$12 -> 1.26 | F21: =F$12*$G10/$G$12 -> 0.98 | G21: =SUM(B21:F21) -> 7 | P21: D | Q21: =Q$12*$G10/$G$12 -> 1.68 | R21: =R$12*$G10/$G$12 -> 1.4 | S21: =S$12*$G10/$G$12 -> 1.68 | T21: =T$12*$G10/$G$12 -> 1.26 | U21: =U$12*$G10/$G$12 -> 0.98 | V21: =SUM(Q21:U21) -> 7
A22: E | B22: =B$12*$G11/$G$12 -> 1.92 | C22: =C$12*$G11/$G$12 -> 1.6 | D22: =D$12*$G11/$G$12 -> 1.92 | E22: =E$12*$G11/$G$12 -> 1.44 | F22: =F$12*$G11/$G$12 -> 1.12 | G22: =SUM(B22:F22) -> 8 | P22: E | Q22: =Q$12*$G11/$G$12 -> 1.92 | R22: =R$12*$G11/$G$12 -> 1.6 | S22: =S$12*$G11/$G$12 -> 1.92 | T22: =T$12*$G11/$G$12 -> 1.44 | U22: =U$12*$G11/$G$12 -> 1.12 | V22: =SUM(Q22:U22) -> 8
A23: Total | B23: =SUM(B18:B22) -> 12 | C23: =SUM(C18:C22) -> 10 | D23: =SUM(D18:D22) -> 12 | E23: =SUM(E18:E22) -> 9 | F23: =SUM(F18:F22) -> 7 | G23: =SUM(B18:F22) -> 50 | P23: Total | Q23: =SUM(Q18:Q22) -> 12 | R23: =SUM(R18:R22) -> 10 | S23: =SUM(S18:S22) -> 12 | T23: =SUM(T18:T22) -> 9 | U23: =SUM(U18:U22) -> 7 | V23: =SUM(Q18:U22) -> 50
A32: Confusion Matrix
I33: Weighted Kappa (Quadratic)
C34: Judge 1 | K34: Weight
A35: Judge 2 | B35: A | C35: B | D35: C | E35: D | F35: E | G35: Total | J35: A | K35: B | L35: C | M35: D | N35: E
A36: A | B36: =B7 -> 7 | C36: =C7 -> 3 | D36: =D7 -> 2 | E36: =E7 -> 1 | F36: =F7 -> 0 | G36: =SUM(B36:F36) -> 13 | I36: A | J36: 0 | K36: 0.0625 | L36: 0.25 | M36: 0.5625 | N36: 1
A37: B | B37: =B8 -> 2 | C37: =C8 -> 6 | D37: =D8 -> 1 | E37: =E8 -> 2 | F37: =F8 -> 1 | G37: =SUM(B37:F37) -> 12 | I37: B | J37: 0.0625 | K37: 0 | L37: 0.0625 | M37: 0.25 | N37: 0.5625
A38: C | B38: =B9 -> 2 | C38: =C9 -> 0 | D38: =D9 -> 7 | E38: =E9 -> 0 | F38: =F9 -> 1 | G38: =SUM(B38:F38) -> 10 | I38: C | J38: 0.25 | K38: 0.0625 | L38: 0 | M38: 0.0625 | N38: 0.25
A39: D | B39: =B10 -> 1 | C39: =C10 -> 1 | D39: =D10 -> 0 | E39: =E10 -> 5 | F39: =F10 -> 0 | G39: =SUM(B39:F39) -> 7 | I39: D | J39: 0.5625 | K39: 0.25 | L39: 0.0625 | M39: 0 | N39: 0.0625
A40: E | B40: =B11 -> 0 | C40: =C11 -> 0 | D40: =D11 -> 2 | E40: =E11 -> 1 | F40: =F11 -> 5 | G40: =SUM(B40:F40) -> 8 | I40: E | J40: 1 | K40: 0.5625 | L40: 0.25 | M40: 0.0625 | N40: 0
A41: Total | B41: =SUM(B36:B39) -> 12 | C41: =SUM(C36:C39) -> 10 | D41: =SUM(D36:D39) -> 10 | E41: =SUM(E36:E39) -> 8 | F41: =SUM(F36:F39) -> 2 | G41: =SUM(B36:F40) -> 50
A43: Expected Matrix
C45: Judge 1
A46: Judge 2 | B46: A | C46: B | D46: C | E46: D | F46: E | G46: Total | I46: Kappa | J46: =1-(L46/L47) -> 0.61337513 | K46: Num: | L46: =SUMPRODUCT(B36:F40,J36:N40) -> 4.625
A47: A | B47: =B$12*$G36/$G$12 -> 3.12 | C47: =C$12*$G36/$G$12 -> 2.6 | D47: =D$12*$G36/$G$12 -> 3.12 | E47: =E$12*$G36/$G$12 -> 2.34 | F47: =F$12*$G36/$G$12 -> 1.82 | G47: =SUM(B47:F47) -> 13 | K47: Den: | L47: =SUMPRODUCT(B47:F51,J36:N40) -> 11.9625
A48: B | B48: =B$12*$G37/$G$12 -> 2.88 | C48: =C$12*$G37/$G$12 -> 2.4 | D48: =D$12*$G37/$G$12 -> 2.88 | E48: =E$12*$G37/$G$12 -> 2.16 | F48: =F$12*$G37/$G$12 -> 1.68 | G48: =SUM(B48:F48) -> 12
A49: C | B49: =B$12*$G38/$G$12 -> 2.4 | C49: =C$12*$G38/$G$12 -> 2 | D49: =D$12*$G38/$G$12 -> 2.4 | E49: =E$12*$G38/$G$12 -> 1.8 | F49: =F$12*$G38/$G$12 -> 1.4 | G49: =SUM(B49:F49) -> 10
A50: D | B50: =B$12*$G39/$G$12 -> 1.68 | C50: =C$12*$G39/$G$12 -> 1.4 | D50: =D$12*$G39/$G$12 -> 1.68 | E50: =E$12*$G39/$G$12 -> 1.26 | F50: =F$12*$G39/$G$12 -> 0.98 | G50: =SUM(B50:F50) -> 7
A51: E | B51: =B$12*$G40/$G$12 -> 1.92 | C51: =C$12*$G40/$G$12 -> 1.6 | D51: =D$12*$G40/$G$12 -> 1.92 | E51: =E$12*$G40/$G$12 -> 1.44 | F51: =F$12*$G40/$G$12 -> 1.12 | G51: =SUM(B51:F51) -> 8
A52: Total | B52: =SUM(B47:B51) -> 12 | C52: =SUM(C47:C51) -> 10 | D52: =SUM(D47:D51) -> 12 | E52: =SUM(E47:E51) -> 9 | F52: =SUM(F47:F51) -> 7 | G52: =SUM(B47:F51) -> 50

Sheet Paradox_5class
A3: Confusion Matrix | P3: Confusion Matrix
I4: Weighted Kappa (Linear) | X4: Unweighted Kappa (Cohen's Kappa)
C5: Judge 1 | K5: Weight | R5: Judge 1 | Z5: Weight
A6: Judge 2 | B6: A | C6: B | D6: C | E6: D | F6: E | G6: Total | J6: A | K6: B | L6: C | M6: D | N6: E | P6: Judge 2 | Q6: A | R6: B | S6: C | T6: D | U6: E | V6: Total | Y6: A | Z6: B | AA6: C | AB6: D | AC6: E
A7: A | B7: 22 | C7: 3 | D7: 2 | E7: 1 | F7: 0 | G7: =SUM(B7:F7) -> 28 | I7: A | J7: 0 | K7: 1 | L7: 2 | M7: 3 | N7: 4 | P7: A | Q7: =B7 -> 22 | R7: =C7 -> 3 | S7: =D7 -> 2 | T7: =E7 -> 1 | U7: =F7 -> 0 | V7: =SUM(Q7:T7) -> 28 | X7: A | Y7: 0 | Z7: 1 | AA7: 1 | AB7: 1 | AC7: 1
A8: B | B8: 2 | C8: 2 | D8: 1 | E8: 2 | F8: 1 | G8: =SUM(B8:F8) -> 8 | I8: B | J8: 1 | K8: 0 | L8: 1 | M8: 2 | N8: 3 | P8: B | Q8: =B8 -> 2 | R8: =C8 -> 2 | S8: =D8 -> 1 | T8: =E8 -> 2 | U8: =F8 -> 1 | V8: =SUM(Q8:T8) -> 7 | X8: B | Y8: 1 | Z8: 0 | AA8: 1 | AB8: 1 | AC8: 1
A9: C | B9: 2 | C9: 0 | D9: 1 | E9: 0 | F9: 1 | G9: =SUM(B9:F9) -> 4 | I9: C | J9: 2 | K9: 1 | L9: 0 | M9: 1 | N9: 2 | P9: C | Q9: =B9 -> 2 | R9: =C9 -> 0 | S9: =D9 -> 1 | T9: =E9 -> 0 | U9: =F9 -> 1 | V9: =SUM(Q9:T9) -> 3 | X9: C | Y9: 1 | Z9: 1 | AA9: 0 | AB9: 1 | AC9: 1
A10: D | B10: 1 | C10: 1 | D10: 0 | E10: 3 | F10: 0 | G10: =SUM(B10:F10) -> 5 | I10: D | J10: 3 | K10: 2 | L10: 1 | M10: 0 | N10: 1 | P10: D | Q10: =B10 -> 1 | R10: =C10 -> 1 | S10: =D10 -> 0 | T10: =E10 -> 3 | U10: =F10 -> 0 | V10: =SUM(Q10:T10) -> 5 | X10: D | Y10: 1 | Z10: 1 | AA10: 1 | AB10: 0 | AC10: 1
A11: E | B11: 0 | C11: 0 | D11: 2 | E11: 1 | F11: 2 | G11: =SUM(B11:F11) -> 5 | I11: E | J11: 4 | K11: 3 | L11: 2 | M11: 1 | N11: 0 | P11: E | Q11: =B11 -> 0 | R11: =C11 -> 0 | S11: =D11 -> 2 | T11: =E11 -> 1 | U11: =F11 -> 2 | V11: =SUM(Q11:T11) -> 3 | X11: E | Y11: 1 | Z11: 1 | AA11: 1 | AB11: 1 | AC11: 0
A12: Total | B12: =SUM(B7:B11) -> 27 | C12: =SUM(C7:C11) -> 6 | D12: =SUM(D7:D11) -> 6 | E12: =SUM(E7:E11) -> 7 | F12: =SUM(F7:F11) -> 4 | G12: =SUM(B7:F11) -> 50 | P12: Total | Q12: =SUM(Q7:Q11) -> 27 | R12: =SUM(R7:R11) -> 6 | S12: =SUM(S7:S11) -> 6 | T12: =SUM(T7:T11) -> 7 | U12: =SUM(U7:U11) -> 4 | V12: =SUM(Q7:U11) -> 50
A14: Expected Matrix | P14: Expected Matrix
C16: Judge 1 | R16: Judge 1
A17: Judge 2 | B17: A | C17: B | D17: C | E17: D | F17: E | G17: Total | I17: Kappa | J17: =1-(M17/M18) -> 0.49324324 | L17: num: | M17: =SUMPRODUCT(B7:F11,J7:N11) -> 36 | P17: Judge 2 | Q17: A | R17: B | S17: C | T17: D | U17: E | V17: Total | X17: Kappa | Y17: =1-(AB17/AB18) -> 0.38157081 | AA17: num: | AB17: =SUMPRODUCT(Q7:U11,Y7:AC11) -> 20
A18: A | B18: =B$12*$G7/$G$12 -> 15.12 | C18: =C$12*$G7/$G$12 -> 3.36 | D18: =D$12*$G7/$G$12 -> 3.36 | E18: =E$12*$G7/$G$12 -> 3.92 | F18: =F$12*$G7/$G$12 -> 2.24 | G18: =SUM(B18:F18) -> 28 | L18: den: | M18: =SUMPRODUCT(B18:F22,J7:N11) -> 71.04 | P18: A | Q18: =Q$12*$G7/$G$12 -> 15.12 | R18: =R$12*$G7/$G$12 -> 3.36 | S18: =S$12*$G7/$G$12 -> 3.36 | T18: =T$12*$G7/$G$12 -> 3.92 | U18: =U$12*$G7/$G$12 -> 2.24 | V18: =SUM(Q18:U18) -> 28 | AA18: den: | AB18: =SUMPRODUCT(Q18:U22,Y7:AC11) -> 32.34
A19: B | B19: =B$12*$G8/$G$12 -> 4.32 | C19: =C$12*$G8/$G$12 -> 0.96 | D19: =D$12*$G8/$G$12 -> 0.96 | E19: =E$12*$G8/$G$12 -> 1.12 | F19: =F$12*$G8/$G$12 -> 0.64 | G19: =SUM(B19:F19) -> 8 | P19: B | Q19: =Q$12*$G8/$G$12 -> 4.32 | R19: =R$12*$G8/$G$12 -> 0.96 | S19: =S$12*$G8/$G$12 -> 0.96 | T19: =T$12*$G8/$G$12 -> 1.12 | U19: =U$12*$G8/$G$12 -> 0.64 | V19: =SUM(Q19:U19) -> 8
A20: C | B20: =B$12*$G9/$G$12 -> 2.16 | C20: =C$12*$G9/$G$12 -> 0.48 | D20: =D$12*$G9/$G$12 -> 0.48 | E20: =E$12*$G9/$G$12 -> 0.56 | F20: =F$12*$G9/$G$12 -> 0.32 | G20: =SUM(B20:F20) -> 4 | L20: K: | M20: =1-(M17/M18) -> 0.49324324 | P20: C | Q20: =Q$12*$G9/$G$12 -> 2.16 | R20: =R$12*$G9/$G$12 -> 0.48 | S20: =S$12*$G9/$G$12 -> 0.48 | T20: =T$12*$G9/$G$12 -> 0.56 | U20: =U$12*$G9/$G$12 -> 0.32 | V20: =SUM(Q20:U20) -> 4 | AA20: K: | AB20: =1-(AB17/AB18) -> 0.38157081
A21: D | B21: =B$12*$G10/$G$12 -> 2.7 | C21: =C$12*$G10/$G$12 -> 0.6 | D21: =D$12*$G10/$G$12 -> 0.6 | E21: =E$12*$G10/$G$12 -> 0.7 | F21: =F$12*$G10/$G$12 -> 0.4 | G21: =SUM(B21:F21) -> 5 | P21: D | Q21: =Q$12*$G10/$G$12 -> 2.7 | R21: =R$12*$G10/$G$12 -> 0.6 | S21: =S$12*$G10/$G$12 -> 0.6 | T21: =T$12*$G10/$G$12 -> 0.7 | U21: =U$12*$G10/$G$12 -> 0.4 | V21: =SUM(Q21:U21) -> 5
A22: E | B22: =B$12*$G11/$G$12 -> 2.7 | C22: =C$12*$G11/$G$12 -> 0.6 | D22: =D$12*$G11/$G$12 -> 0.6 | E22: =E$12*$G11/$G$12 -> 0.7 | F22: =F$12*$G11/$G$12 -> 0.4 | G22: =SUM(B22:F22) -> 5 | P22: E | Q22: =Q$12*$G11/$G$12 -> 2.7 | R22: =R$12*$G11/$G$12 -> 0.6 | S22: =S$12*$G11/$G$12 -> 0.6 | T22: =T$12*$G11/$G$12 -> 0.7 | U22: =U$12*$G11/$G$12 -> 0.4 | V22: =SUM(Q22:U22) -> 5
A23: Total | B23: =SUM(B18:B22) -> 27 | C23: =SUM(C18:C22) -> 6 | D23: =SUM(D18:D22) -> 6 | E23: =SUM(E18:E22) -> 7 | F23: =SUM(F18:F22) -> 4 | G23: =SUM(B18:F22) -> 50 | P23: Total | Q23: =SUM(Q18:Q22) -> 27 | R23: =SUM(R18:R22) -> 6 | S23: =SUM(S18:S22) -> 6 | T23: =SUM(T18:T22) -> 7 | U23: =SUM(U18:U22) -> 4 | V23: =SUM(Q18:U22) -> 50
A32: Confusion Matrix
I33: Weighted Kappa (Quadratic)
C34: Judge 1 | K34: Weight
A35: Judge 2 | B35: A | C35: B | D35: C | E35: D | F35: E | G35: Total | J35: A | K35: B | L35: C | M35: D | N35: E
A36: A | B36: =B7 -> 22 | C36: =C7 -> 3 | D36: =D7 -> 2 | E36: =E7 -> 1 | F36: =F7 -> 0 | G36: =SUM(B36:F36) -> 28 | I36: A | J36: 0 | K36: 0.0625 | L36: 0.25 | M36: 0.5625 | N36: 1
A37: B | B37: =B8 -> 2 | C37: =C8 -> 2 | D37: =D8 -> 1 | E37: =E8 -> 2 | F37: =F8 -> 1 | G37: =SUM(B37:F37) -> 8 | I37: B | J37: 0.0625 | K37: 0 | L37: 0.0625 | M37: 0.25 | N37: 0.5625
A38: C | B38: =B9 -> 2 | C38: =C9 -> 0 | D38: =D9 -> 1 | E38: =E9 -> 0 | F38: =F9 -> 1 | G38: =SUM(B38:F38) -> 4 | I38: C | J38: 0.25 | K38: 0.0625 | L38: 0 | M38: 0.0625 | N38: 0.25
A39: D | B39: =B10 -> 1 | C39: =C10 -> 1 | D39: =D10 -> 0 | E39: =E10 -> 3 | F39: =F10 -> 0 | G39: =SUM(B39:F39) -> 5 | I39: D | J39: 0.5625 | K39: 0.25 | L39: 0.0625 | M39: 0 | N39: 0.0625
A40: E | B40: =B11 -> 0 | C40: =C11 -> 0 | D40: =D11 -> 2 | E40: =E11 -> 1 | F40: =F11 -> 2 | G40: =SUM(B40:F40) -> 5 | I40: E | J40: 1 | K40: 0.5625 | L40: 0.25 | M40: 0.0625 | N40: 0
A41: Total | B41: =SUM(B36:B39) -> 27 | C41: =SUM(C36:C39) -> 6 | D41: =SUM(D36:D39) -> 4 | E41: =SUM(E36:E39) -> 6 | F41: =SUM(F36:F39) -> 2 | G41: =SUM(B36:F40) -> 50
A43: Expected Matrix
C45: Judge 1
A46: Judge 2 | B46: A | C46: B | D46: C | E46: D | F46: E | G46: Total | I46: Kappa | J46: =1-(L46/L47) -> 0.61816305 | K46: Num: | L46: =SUMPRODUCT(B36:F40,J36:N40) -> 4.625
A47: A | B47: =B$12*$G36/$G$12 -> 15.12 | C47: =C$12*$G36/$G$12 -> 3.36 | D47: =D$12*$G36/$G$12 -> 3.36 | E47: =E$12*$G36/$G$12 -> 3.92 | F47: =F$12*$G36/$G$12 -> 2.24 | G47: =SUM(B47:F47) -> 28 | K47: Den: | L47: =SUMPRODUCT(B47:F51,J36:N40) -> 12.1125
A48: B | B48: =B$12*$G37/$G$12 -> 4.32 | C48: =C$12*$G37/$G$12 -> 0.96 | D48: =D$12*$G37/$G$12 -> 0.96 | E48: =E$12*$G37/$G$12 -> 1.12 | F48: =F$12*$G37/$G$12 -> 0.64 | G48: =SUM(B48:F48) -> 8
A49: C | B49: =B$12*$G38/$G$12 -> 2.16 | C49: =C$12*$G38/$G$12 -> 0.48 | D49: =D$12*$G38/$G$12 -> 0.48 | E49: =E$12*$G38/$G$12 -> 0.56 | F49: =F$12*$G38/$G$12 -> 0.32 | G49: =SUM(B49:F49) -> 4
A50: D | B50: =B$12*$G39/$G$12 -> 2.7 | C50: =C$12*$G39/$G$12 -> 0.6 | D50: =D$12*$G39/$G$12 -> 0.6 | E50: =E$12*$G39/$G$12 -> 0.7 | F50: =F$12*$G39/$G$12 -> 0.4 | G50: =SUM(B50:F50) -> 5
A51: E | B51: =B$12*$G40/$G$12 -> 2.7 | C51: =C$12*$G40/$G$12 -> 0.6 | D51: =D$12*$G40/$G$12 -> 0.6 | E51: =E$12*$G40/$G$12 -> 0.7 | F51: =F$12*$G40/$G$12 -> 0.4 | G51: =SUM(B51:F51) -> 5
A52: Total | B52: =SUM(B47:B51) -> 27 | C52: =SUM(C47:C51) -> 6 | D52: =SUM(D47:D51) -> 6 | E52: =SUM(E47:E51) -> 7 | F52: =SUM(F47:F51) -> 4 | G52: =SUM(B47:F51) -> 50

Sheet WK_6class
A3: Confusion Matrix | R3: Confusion Matrix
J4: Weighted Kappa (Linear) | AA4: Unweighted Kappa (Cohen's Kappa)
C5: Judge 1 | L5: Weight | T5: Judge 1 | AC5: Weight
A6: Judge 2 | B6: A | C6: B | D6: C | E6: D | F6: E | G6: F | H6: Total | K6: A | L6: B | M6: C | N6: D | O6: E | P6: F | R6: Judge 2 | S6: A | T6: B | U6: C | V6: D | W6: E | X6: F | Y6: Total | AB6: A | AC6: B | AD6: C | AE6: D | AF6: E | AG6: F
A7: A | B7: 6 | C7: 2 | D7: 1 | E7: 1 | F7: 0 | G7: 1 | H7: =SUM(B7:G7) -> 11 | J7: A | K7: 0 | L7: 1 | M7: 2 | N7: 3 | O7: 4 | P7: 5 | R7: A | S7: =B7 -> 6 | T7: =C7 -> 2 | U7: =D7 -> 1 | V7: =E7 -> 1 | W7: =F7 -> 0 | X7: =G7 -> 1 | Y7: =SUM(S7:X7) -> 11 | AA7: A | AB7: 0 | AC7: 1 | AD7: 1 | AE7: 1 | AF7: 1 | AG7: 1
A8: B | B8: 2 | C8: 5 | D8: 1 | E8: 2 | F8: 1 | G8: 1 | H8: =SUM(B8:G8) -> 12 | J8: B | K8: 1 | L8: 0 | M8: 1 | N8: 2 | O8: 3 | P8: 4 | R8: B | S8: =B8 -> 2 | T8: =C8 -> 5 | U8: =D8 -> 1 | V8: =E8 -> 2 | W8: =F8 -> 1 | X8: =G8 -> 1 | Y8: =SUM(S8:X8) -> 12 | AA8: B | AB8: 1 | AC8: 0 | AD8: 1 | AE8: 1 | AF8: 1 | AG8: 1
A9: C | B9: 1 | C9: 0 | D9: 4 | E9: 0 | F9: 1 | G9: 0 | H9: =SUM(B9:G9) -> 6 | J9: C | K9: 2 | L9: 1 | M9: 0 | N9: 1 | O9: 2 | P9: 3 | R9: C | S9: =B9 -> 1 | T9: =C9 -> 0 | U9: =D9 -> 4 | V9: =E9 -> 0 | W9: =F9 -> 1 | X9: =G9 -> 0 | Y9: =SUM(S9:X9) -> 6 | AA9: C | AB9: 1 | AC9: 1 | AD9: 0 | AE9: 1 | AF9: 1 | AG9: 1
A10: D | B10: 1 | C10: 1 | D10: 0 | E10: 4 | F10: 0 | G10: 1 | H10: =SUM(B10:G10) -> 7 | J10: D | K10: 3 | L10: 2 | M10: 1 | N10: 0 | O10: 1 | P10: 2 | R10: D | S10: =B10 -> 1 | T10: =C10 -> 1 | U10: =D10 -> 0 | V10: =E10 -> 4 | W10: =F10 -> 0 | X10: =G10 -> 1 | Y10: =SUM(S10:X10) -> 7 | AA10: D | AB10: 1 | AC10: 1 | AD10: 1 | AE10: 0 | AF10: 1 | AG10: 1
A11: E | B11: 0 | C11: 0 | D11: 2 | E11: 1 | F11: 3 | G11: 1 | H11: =SUM(B11:G11) -> 7 | J11: E | K11: 4 | L11: 3 | M11: 2 | N11: 1 | O11: 0 | P11: 1 | R11: E | S11: =B11 -> 0 | T11: =C11 -> 0 | U11: =D11 -> 2 | V11: =E11 -> 1 | W11: =F11 -> 3 | X11: =G11 -> 1 | Y11: =SUM(S11:X11) -> 7 | AA11: E | AB11: 1 | AC11: 1 | AD11: 1 | AE11: 1 | AF11: 0 | AG11: 1
A12: F | B12: 0 | C12: 1 | D12: 0 | E12: 2 | F12: 0 | G12: 4 | H12: =SUM(B12:G12) -> 7 | J12: F | K12: 5 | L12: 4 | M12: 3 | N12: 2 | O12: 1 | P12: 0 | R12: F | S12: =B12 -> 0 | T12: =C12 -> 1 | U12: =D12 -> 0 | V12: =E12 -> 2 | W12: =F12 -> 0 | X12: =G12 -> 4 | Y12: =SUM(S12:X12) -> 7 | AA12: F | AB12: 1 | AC12: 1 | AD12: 1 | AE12: 1 | AF12: 1 | AG12: 0
A13: Total | B13: =SUM(B7:B12) -> 10 | C13: =SUM(C7:C12) -> 9 | D13: =SUM(D7:D12) -> 8 | E13: =SUM(E7:E12) -> 10 | F13: =SUM(F7:F12) -> 5 | G13: =SUM(G7:G12) -> 8 | H13: =SUM(B7:G12) -> 50 | R13: Total | S13: =SUM(S7:S12) -> 10 | T13: =SUM(T7:T12) -> 9 | U13: =SUM(U7:U12) -> 8 | V13: =SUM(V7:V12) -> 10 | W13: =SUM(W7:W12) -> 5 | X13: =SUM(X7:X12) -> 8 | Y13: =SUM(S7:X12) -> 50
A15: Expected Matrix | R15: Expected Matrix
C17: Judge 1 | T17: Judge 1
A18: Judge 2 | B18: A | C18: B | D18: C | E18: D | F18: E | G18: F | H18: Total | J18: Kappa | K18: =1-(N18/N19) -> 0.48107448 | M18: num: | N18: =SUMPRODUCT(B7:G12,K7:P12) -> 51 | R18: Judge 2 | S18: A | T18: B | U18: C | V18: D | W18: E | X18: F | Y18: Total | AA18: Kappa | AB18: =1-(AE18/AE19) -> 0.4211288 | AD18: num: | AE18: =SUMPRODUCT(S7:X12,AB7:AG12) -> 24
A19: A | B19: =B$13*$H7/$H$13 -> 2.2 | C19: =C$13*$H7/$H$13 -> 1.98 | D19: =D$13*$H7/$H$13 -> 1.76 | E19: =E$13*$H7/$H$13 -> 2.2 | F19: =F$13*$H7/$H$13 -> 1.1 | G19: =G$13*$H7/$H$13 -> 1.76 | H19: =SUM(B19:G19) -> 11 | M19: den: | N19: =SUMPRODUCT(B19:G24,K7:P12) -> 98.28 | R19: A | S19: =S$13*$H7/$H$13 -> 2.2 | T19: =T$13*$H7/$H$13 -> 1.98 | U19: =U$13*$H7/$H$13 -> 1.76 | V19: =V$13*$H7/$H$13 -> 2.2 | W19: =W$13*$H7/$H$13 -> 1.1 | X19: =X$13*$H7/$H$13 -> 1.76 | Y19: =SUM(S19:X19) -> 11 | AD19: den: | AE19: =SUMPRODUCT(S19:X24,AB7:AG12) -> 41.46
A20: B | B20: =B$13*$H8/$H$13 -> 2.4 | C20: =C$13*$H8/$H$13 -> 2.16 | D20: =D$13*$H8/$H$13 -> 1.92 | E20: =E$13*$H8/$H$13 -> 2.4 | F20: =F$13*$H8/$H$13 -> 1.2 | G20: =G$13*$H8/$H$13 -> 1.92 | H20: =SUM(B20:G20) -> 12 | R20: B | S20: =S$13*$H8/$H$13 -> 2.4 | T20: =T$13*$H8/$H$13 -> 2.16 | U20: =U$13*$H8/$H$13 -> 1.92 | V20: =V$13*$H8/$H$13 -> 2.4 | W20: =W$13*$H8/$H$13 -> 1.2 | X20: =X$13*$H8/$H$13 -> 1.92 | Y20: =SUM(S20:X20) -> 12
A21: C | B21: =B$13*$H9/$H$13 -> 1.2 | C21: =C$13*$H9/$H$13 -> 1.08 | D21: =D$13*$H9/$H$13 -> 0.96 | E21: =E$13*$H9/$H$13 -> 1.2 | F21: =F$13*$H9/$H$13 -> 0.6 | G21: =G$13*$H9/$H$13 -> 0.96 | H21: =SUM(B21:G21) -> 6 | M21: K: | N21: =1-(N18/N19) -> 0.48107448 | R21: C | S21: =S$13*$H9/$H$13 -> 1.2 | T21: =T$13*$H9/$H$13 -> 1.08 | U21: =U$13*$H9/$H$13 -> 0.96 | V21: =V$13*$H9/$H$13 -> 1.2 | W21: =W$13*$H9/$H$13 -> 0.6 | X21: =X$13*$H9/$H$13 -> 0.96 | Y21: =SUM(S21:X21) -> 6 | AD21: K: | AE21: =1-(AE18/AE19) -> 0.4211288
A22: D | B22: =B$13*$H10/$H$13 -> 1.4 | C22: =C$13*$H10/$H$13 -> 1.26 | D22: =D$13*$H10/$H$13 -> 1.12 | E22: =E$13*$H10/$H$13 -> 1.4 | F22: =F$13*$H10/$H$13 -> 0.7 | G22: =G$13*$H10/$H$13 -> 1.12 | H22: =SUM(B22:G22) -> 7 | R22: D | S22: =S$13*$H10/$H$13 -> 1.4 | T22: =T$13*$H10/$H$13 -> 1.26 | U22: =U$13*$H10/$H$13 -> 1.12 | V22: =V$13*$H10/$H$13 -> 1.4 | W22: =W$13*$H10/$H$13 -> 0.7 | X22: =X$13*$H10/$H$13 -> 1.12 | Y22: =SUM(S22:X22) -> 7
A23: E | B23: =B$13*$H11/$H$13 -> 1.4 | C23: =C$13*$H11/$H$13 -> 1.26 | D23: =D$13*$H11/$H$13 -> 1.12 | E23: =E$13*$H11/$H$13 -> 1.4 | F23: =F$13*$H11/$H$13 -> 0.7 | G23: =G$13*$H11/$H$13 -> 1.12 | H23: =SUM(B23:G23) -> 7 | R23: E | S23: =S$13*$H11/$H$13 -> 1.4 | T23: =T$13*$H11/$H$13 -> 1.26 | U23: =U$13*$H11/$H$13 -> 1.12 | V23: =V$13*$H11/$H$13 -> 1.4 | W23: =W$13*$H11/$H$13 -> 0.7 | X23: =X$13*$H11/$H$13 -> 1.12 | Y23: =SUM(S23:X23) -> 7
A24: F | B24: =B$13*$H12/$H$13 -> 1.4 | C24: =C$13*$H12/$H$13 -> 1.26 | D24: =D$13*$H12/$H$13 -> 1.12 | E24: =E$13*$H12/$H$13 -> 1.4 | F24: =F$13*$H12/$H$13 -> 0.7 | G24: =G$13*$H12/$H$13 -> 1.12 | H24: =SUM(B24:G24) -> 7 | R24: F | S24: =S$13*$H12/$H$13 -> 1.4 | T24: =T$13*$H12/$H$13 -> 1.26 | U24: =U$13*$H12/$H$13 -> 1.12 | V24: =V$13*$H12/$H$13 -> 1.4 | W24: =W$13*$H12/$H$13 -> 0.7 | X24: =X$13*$H12/$H$13 -> 1.12 | Y24: =SUM(S24:X24) -> 7
A25: Total | B25: =SUM(B19:B24) -> 10 | C25: =SUM(C19:C24) -> 9 | D25: =SUM(D19:D24) -> 8 | E25: =SUM(E19:E24) -> 10 | F25: =SUM(F19:F24) -> 5 | G25: =SUM(G19:G24) -> 8 | H25: =SUM(B19:G24) -> 50 | R25: Total | S25: =SUM(S19:S24) -> 10 | T25: =SUM(T19:T24) -> 9 | U25: =SUM(U19:U24) -> 8 | V25: =SUM(V19:V24) -> 10 | W25: =SUM(W19:W24) -> 5 | X25: =SUM(X19:X24) -> 8 | Y25: =SUM(S19:X24) -> 50
A33: Confusion Matrix
J34: Weighted Kappa (Quadratic)
C35: Judge 1 | L35: Weight
A36: Judge 2 | B36: A | C36: B | D36: C | E36: D | F36: E | G36: F | H36: Total | K36: A | L36: B | M36: C | N36: D | O36: E | P36: F
A37: A | B37: =B7 -> 6 | C37: =C7 -> 2 | D37: =D7 -> 1 | E37: =E7 -> 1 | F37: =F7 -> 0 | G37: =G7 -> 1 | H37: =SUM(B37:G37) -> 11 | J37: A | K37: 0 | L37: 0.04 | M37: 0.16 | N37: 0.36 | O37: 0.64 | P37: 1
A38: B | B38: =B8 -> 2 | C38: =C8 -> 5 | D38: =D8 -> 1 | E38: =E8 -> 2 | F38: =F8 -> 1 | G38: =G8 -> 1 | H38: =SUM(B38:G38) -> 12 | J38: B | K38: 0.04 | L38: 0 | M38: 0.04 | N38: 0.16 | O38: 0.36 | P38: 0.64
A39: C | B39: =B9 -> 1 | C39: =C9 -> 0 | D39: =D9 -> 4 | E39: =E9 -> 0 | F39: =F9 -> 1 | G39: =G9 -> 0 | H39: =SUM(B39:G39) -> 6 | J39: C | K39: 0.16 | L39: 0.04 | M39: 0 | N39: 0.04 | O39: 0.16 | P39: 0.36
A40: D | B40: =B10 -> 1 | C40: =C10 -> 1 | D40: =D10 -> 0 | E40: =E10 -> 4 | F40: =F10 -> 0 | G40: =G10 -> 1 | H40: =SUM(B40:G40) -> 7 | J40: D | K40: 0.36 | L40: 0.16 | M40: 0.04 | N40: 0 | O40: 0.04 | P40: 0.16
A41: E | B41: =B11 -> 0 | C41: =C11 -> 0 | D41: =D11 -> 2 | E41: =E11 -> 1 | F41: =F11 -> 3 | G41: =G11 -> 1 | H41: =SUM(B41:G41) -> 7 | J41: E | K41: 0.64 | L41: 0.36 | M41: 0.16 | N41: 0.04 | O41: 0 | P41: 0.04
A42: F | B42: =B12 -> 0 | C42: =C12 -> 1 | D42: =D12 -> 0 | E42: =E12 -> 2 | F42: =F12 -> 0 | G42: =G12 -> 4 | H42: =SUM(B42:G42) -> 7 | J42: F | K42: 1 | L42: 0.64 | M42: 0.36 | N42: 0.16 | O42: 0.04 | P42: 0
A43: Total | B43: =SUM(B37:B42) -> 10 | C43: =SUM(C37:C42) -> 9 | D43: =SUM(D37:D42) -> 8 | E43: =SUM(E37:E42) -> 10 | F43: =SUM(F37:F42) -> 5 | G43: =SUM(G37:G42) -> 8 | H43: =SUM(B37:G42) -> 50
A45: Expected Matrix
C47: Judge 1
A48: Judge 2 | B48: A | C48: B | D48: C | E48: D | F48: E | G48: F | H48: Total | J48: Kappa | K48: =1-(M48/M49) -> 0.5502998 | L48: Num: | M48: =SUMPRODUCT(B37:G42,K37:P42) -> 5.4
A49: A | B49: =B$13*$H37/$H$13 -> 2.2 | C49: =C$13*$H37/$H$13 -> 1.98 | D49: =D$13*$H37/$H$13 -> 1.76 | E49: =E$13*$H37/$H$13 -> 2.2 | F49: =F$13*$H37/$H$13 -> 1.1 | G49: =G$13*$H37/$H$13 -> 1.76 | H49: =SUM(B49:G49) -> 11 | L49: Den: | M49: =SUMPRODUCT(B49:G54,K37:P42) -> 12.008
A50: B | B50: =B$13*$H38/$H$13 -> 2.4 | C50: =C$13*$H38/$H$13 -> 2.16 | D50: =D$13*$H38/$H$13 -> 1.92 | E50: =E$13*$H38/$H$13 -> 2.4 | F50: =F$13*$H38/$H$13 -> 1.2 | G50: =G$13*$H38/$H$13 -> 1.92 | H50: =SUM(B50:G50) -> 12
A51: C | B51: =B$13*$H39/$H$13 -> 1.2 | C51: =C$13*$H39/$H$13 -> 1.08 | D51: =D$13*$H39/$H$13 -> 0.96 | E51: =E$13*$H39/$H$13 -> 1.2 | F51: =F$13*$H39/$H$13 -> 0.6 | G51: =G$13*$H39/$H$13 -> 0.96 | H51: =SUM(B51:G51) -> 6
A52: D | B52: =B$13*$H40/$H$13 -> 1.4 | C52: =C$13*$H40/$H$13 -> 1.26 | D52: =D$13*$H40/$H$13 -> 1.12 | E52: =E$13*$H40/$H$13 -> 1.4 | F52: =F$13*$H40/$H$13 -> 0.7 | G52: =G$13*$H40/$H$13 -> 1.12 | H52: =SUM(B52:G52) -> 7
A53: E | B53: =B$13*$H41/$H$13 -> 1.4 | C53: =C$13*$H41/$H$13 -> 1.26 | D53: =D$13*$H41/$H$13 -> 1.12 | E53: =E$13*$H41/$H$13 -> 1.4 | F53: =F$13*$H41/$H$13 -> 0.7 | G53: =G$13*$H41/$H$13 -> 1.12 | H53: =SUM(B53:G53) -> 7
...

Sheet Paradox_6class
A3: Confusion Matrix | R3: Confusion Matrix
J4: Weighted Kappa (Linear) | AA4: Unweighted Kappa (Cohen's Kappa)
C5: Judge 1 | L5: Weight | T5: Judge 1 | AC5: Weight
A6: Judge 2 | B6: A | C6: B | D6: C | E6: D | F6: E | G6: F | H6: Total | K6: A | L6: B | M6: C | N6: D | O6: E | P6: F | R6: Judge 2 | S6: A | T6: B | U6: C | V6: D | W6: E | X6: F | Y6: Total | AB6: A | AC6: B | AD6: C | AE6: D | AF6: E | AG6: F
A7: A | B7: 15 | C7: 2 | D7: 1 | E7: 1 | F7: 0 | G7: 1 | H7: =SUM(B7:G7) -> 20 | J7: A | K7: 0 | L7: 1 | M7: 2 | N7: 3 | O7: 4 | P7: 5 | R7: A | S7: =B7 -> 15 | T7: =C7 -> 2 | U7: =D7 -> 1 | V7: =E7 -> 1 | W7: =F7 -> 0 | X7: =G7 -> 1 | Y7: =SUM(S7:X7) -> 20 | AA7: A | AB7: 0 | AC7: 1 | AD7: 1 | AE7: 1 | AF7: 1 | AG7: 1
A8: B | B8: 2 | C8: 2 | D8: 1 | E8: 2 | F8: 1 | G8: 1 | H8: =SUM(B8:G8) -> 9 | J8: B | K8: 1 | L8: 0 | M8: 1 | N8: 2 | O8: 3 | P8: 4 | R8: B | S8: =B8 -> 2 | T8: =C8 -> 2 | U8: =D8 -> 1 | V8: =E8 -> 2 | W8: =F8 -> 1 | X8: =G8 -> 1 | Y8: =SUM(S8:X8) -> 9 | AA8: B | AB8: 1 | AC8: 0 | AD8: 1 | AE8: 1 | AF8: 1 | AG8: 1
A9: C | B9: 1 | C9: 0 | D9: 3 | E9: 0 | F9: 1 | G9: 0 | H9: =SUM(B9:G9) -> 5 | J9: C | K9: 2 | L9: 1 | M9: 0 | N9: 1 | O9: 2 | P9: 3 | R9: C | S9: =B9 -> 1 | T9: =C9 -> 0 | U9: =D9 -> 3 | V9: =E9 -> 0 | W9: =F9 -> 1 | X9: =G9 -> 0 | Y9: =SUM(S9:X9) -> 5 | AA9: C | AB9: 1 | AC9: 1 | AD9: 0 | AE9: 1 | AF9: 1 | AG9: 1
A10: D | B10: 1 | C10: 1 | D10: 0 | E10: 2 | F10: 0 | G10: 1 | H10: =SUM(B10:G10) -> 5 | J10: D | K10: 3 | L10: 2 | M10: 1 | N10: 0 | O10: 1 | P10: 2 | R10: D | S10: =B10 -> 1 | T10: =C10 -> 1 | U10: =D10 -> 0 | V10: =E10 -> 2 | W10: =F10 -> 0 | X10: =G10 -> 1 | Y10: =SUM(S10:X10) -> 5 | AA10: D | AB10: 1 | AC10: 1 | AD10: 1 | AE10: 0 | AF10: 1 | AG10: 1
A11: E | B11: 0 | C11: 0 | D11: 2 | E11: 1 | F11: 1 | G11: 1 | H11: =SUM(B11:G11) -> 5 | J11: E | K11: 4 | L11: 3 | M11: 2 | N11: 1 | O11: 0 | P11: 1 | R11: E | S11: =B11 -> 0 | T11: =C11 -> 0 | U11: =D11 -> 2 | V11: =E11 -> 1 | W11: =F11 -> 1 | X11: =G11 -> 1 | Y11: =SUM(S11:X11) -> 5 | AA11: E | AB11: 1 | AC11: 1 | AD11: 1 | AE11: 1 | AF11: 0 | AG11: 1
A12: F | B12: 0 | C12: 1 | D12: 0 | E12: 2 | F12: 0 | G12: 3 | H12: =SUM(B12:G12) -> 6 | J12: F | K12: 5 | L12: 4 | M12: 3 | N12: 2 | O12: 1 | P12: 0 | R12: F | S12: =B12 -> 0 | T12: =C12 -> 1 | U12: =D12 -> 0 | V12: =E12 -> 2 | W12: =F12 -> 0 | X12: =G12 -> 3 | Y12: =SUM(S12:X12) -> 6 | AA12: F | AB12: 1 | AC12: 1 | AD12: 1 | AE12: 1 | AF12: 1 | AG12: 0
A13: Total | B13: =SUM(B7:B12) -> 19 | C13: =SUM(C7:C12) -> 6 | D13: =SUM(D7:D12) -> 7 | E13: =SUM(E7:E12) -> 8 | F13: =SUM(F7:F12) -> 3 | G13: =SUM(G7:G12) -> 7 | H13: =SUM(B7:G12) -> 50 | R13: Total | S13: =SUM(S7:S12) -> 19 | T13: =SUM(T7:T12) -> 6 | U13: =SUM(U7:U12) -> 7 | V13: =SUM(V7:V12) -> 8 | W13: =SUM(W7:W12) -> 3 | X13: =SUM(X7:X12) -> 7 | Y13: =SUM(S7:X12) -> 50
A15: Expected Matrix | R15: Expected Matrix
C17: Judge 1 | T17: Judge 1
A18: Judge 2 | B18: A | C18: B | D18: C | E18: D | F18: E | G18: F | H18: Total | J18: Kappa | K18: =1-(N18/N19) -> 0.4858871 | M18: num: | N18: =SUMPRODUCT(B7:G12,K7:P12) -> 51 | R18: Judge 2 | S18: A | T18: B | U18: C | V18: D | W18: E | X18: F | Y18: Total | AA18: Kappa | AB18: =1-(AE18/AE19) -> 0.3795243 | AD18: num: | AE18: =SUMPRODUCT(S7:X12,AB7:AG12) -> 24
A19: A | B19: =B$13*$H7/$H$13 -> 7.6 | C19: =C$13*$H7/$H$13 -> 2.4 | D19: =D$13*$H7/$H$13 -> 2.8 | E19: =E$13*$H7/$H$13 -> 3.2 | F19: =F$13*$H7/$H$13 -> 1.2 | G19: =G$13*$H7/$H$13 -> 2.8 | H19: =SUM(B19:G19) -> 20 | M19: den: | N19: =SUMPRODUCT(B19:G24,K7:P12) -> 99.2 | R19: A | S19: =S$13*$H7/$H$13 -> 7.6 | T19: =T$13*$H7/$H$13 -> 2.4 | U19: =U$13*$H7/$H$13 -> 2.8 | V19: =V$13*$H7/$H$13 -> 3.2 | W19: =W$13*$H7/$H$13 -> 1.2 | X19: =X$13*$H7/$H$13 -> 2.8 | Y19: =SUM(S19:X19) -> 20 | AD19: den: | AE19: =SUMPRODUCT(S19:X24,AB7:AG12) -> 38.68
A20: B | B20: =B$13*$H8/$H$13 -> 3.42 | C20: =C$13*$H8/$H$13 -> 1.08 | D20: =D$13*$H8/$H$13 -> 1.26 | E20: =E$13*$H8/$H$13 -> 1.44 | F20: =F$13*$H8/$H$13 -> 0.54 | G20: =G$13*$H8/$H$13 -> 1.26 | H20: =SUM(B20:G20) -> 9 | R20: B | S20: =S$13*$H8/$H$13 -> 3.42 | T20: =T$13*$H8/$H$13 -> 1.08 | U20: =U$13*$H8/$H$13 -> 1.26 | V20: =V$13*$H8/$H$13 -> 1.44 | W20: =W$13*$H8/$H$13 -> 0.54 | X20: =X$13*$H8/$H$13 -> 1.26 | Y20: =SUM(S20:X20) -> 9
A21: C | B21: =B$13*$H9/$H$13 -> 1.9 | C21: =C$13*$H9/$H$13 -> 0.6 | D21: =D$13*$H9/$H$13 -> 0.7 | E21: =E$13*$H9/$H$13 -> 0.8 | F21: =F$13*$H9/$H$13 -> 0.3 | G21: =G$13*$H9/$H$13 -> 0.7 | H21: =SUM(B21:G21) -> 5 | M21: K: | N21: =1-(N18/N19) -> 0.4858871 | R21: C | S21: =S$13*$H9/$H$13 -> 1.9 | T21: =T$13*$H9/$H$13 -> 0.6 | U21: =U$13*$H9/$H$13 -> 0.7 | V21: =V$13*$H9/$H$13 -> 0.8 | W21: =W$13*$H9/$H$13 -> 0.3 | X21: =X$13*$H9/$H$13 -> 0.7 | Y21: =SUM(S21:X21) -> 5 | AD21: K: | AE21: =1-(AE18/AE19) -> 0.3795243
A22: D | B22: =B$13*$H10/$H$13 -> 1.9 | C22: =C$13*$H10/$H$13 -> 0.6 | D22: =D$13*$H10/$H$13 -> 0.7 | E22: =E$13*$H10/$H$13 -> 0.8 | F22: =F$13*$H10/$H$13 -> 0.3 | G22: =G$13*$H10/$H$13 -> 0.7 | H22: =SUM(B22:G22) -> 5 | R22: D | S22: =S$13*$H10/$H$13 -> 1.9 | T22: =T$13*$H10/$H$13 -> 0.6 | U22: =U$13*$H10/$H$13 -> 0.7 | V22: =V$13*$H10/$H$13 -> 0.8 | W22: =W$13*$H10/$H$13 -> 0.3 | X22: =X$13*$H10/$H$13 -> 0.7 | Y22: =SUM(S22:X22) -> 5
A23: E | B23: =B$13*$H11/$H$13 -> 1.9 | C23: =C$13*$H11/$H$13 -> 0.6 | D23: =D$13*$H11/$H$13 -> 0.7 | E23: =E$13*$H11/$H$13 -> 0.8 | F23: =F$13*$H11/$H$13 -> 0.3 | G23: =G$13*$H11/$H$13 -> 0.7 | H23: =SUM(B23:G23) -> 5 | R23: E | S23: =S$13*$H11/$H$13 -> 1.9 | T23: =T$13*$H11/$H$13 -> 0.6 | U23: =U$13*$H11/$H$13 -> 0.7 | V23: =V$13*$H11/$H$13 -> 0.8 | W23: =W$13*$H11/$H$13 -> 0.3 | X23: =X$13*$H11/$H$13 -> 0.7 | Y23: =SUM(S23:X23) -> 5
A24: F | B24: =B$13*$H12/$H$13 -> 2.28 | C24: =C$13*$H12/$H$13 -> 0.72 | D24: =D$13*$H12/$H$13 -> 0.84 | E24: =E$13*$H12/$H$13 -> 0.96 | F24: =F$13*$H12/$H$13 -> 0.36 | G24: =G$13*$H12/$H$13 -> 0.84 | H24: =SUM(B24:G24) -> 6 | R24: F | S24: =S$13*$H12/$H$13 -> 2.28 | T24: =T$13*$H12/$H$13 -> 0.72 | U24: =U$13*$H12/$H$13 -> 0.84 | V24: =V$13*$H12/$H$13 -> 0.96 | W24: =W$13*$H12/$H$13 -> 0.36 | X24: =X$13*$H12/$H$13 -> 0.84 | Y24: =SUM(S24:X24) -> 6
A25: Total | B25: =SUM(B19:B24) -> 19 | C25: =SUM(C19:C24) -> 6 | D25: =SUM(D19:D24) -> 7 | E25: =SUM(E19:E24) -> 8 | F25: =SUM(F19:F24) -> 3 | G25: =SUM(G19:G24) -> 7 | H25: =SUM(B19:G24) -> 50 | R25: Total | S25: =SUM(S19:S24) -> 19 | T25: =SUM(T19:T24) -> 6 | U25: =SUM(U19:U24) -> 7 | V25: =SUM(V19:V24) -> 8 | W25: =SUM(W19:W24) -> 3 | X25: =SUM(X19:X24) -> 7 | Y25: =SUM(S19:X24) -> 50
A33: Confusion Matrix
J34: Weighted Kappa (Quadratic)
C35: Judge 1 | L35: Weight
A36: Judge 2 | B36: A | C36: B | D36: C | E36: D | F36: E | G36: F | H36: Total | K36: A | L36: B | M36: C | N36: D | O36: E | P36: F
A37: A | B37: =B7 -> 15 | C37: =C7 -> 2 | D37: =D7 -> 1 | E37: =E7 -> 1 | F37: =F7 -> 0 | G37: =G7 -> 1 | H37: =SUM(B37:G37) -> 20 | J37: A | K37: 0 | L37: 0.04 | M37: 0.16 | N37: 0.36 | O37: 0.64 | P37: 1
A38: B | B38: =B8 -> 2 | C38: =C8 -> 2 | D38: =D8 -> 1 | E38: =E8 -> 2 | F38: =F8 -> 1 | G38: =G8 -> 1 | H38: =SUM(B38:G38) -> 9 | J38: B | K38: 0.04 | L38: 0 | M38: 0.04 | N38: 0.16 | O38: 0.36 | P38: 0.64
A39: C | B39: =B9 -> 1 | C39: =C9 -> 0 | D39: =D9 -> 3 | E39: =E9 -> 0 | F39: =F9 -> 1 | G39: =G9 -> 0 | H39: =SUM(B39:G39) -> 5 | J39: C | K39: 0.16 | L39: 0.04 | M39: 0 | N39: 0.04 | O39: 0.16 | P39: 0.36
A40: D | B40: =B10 -> 1 | C40: =C10 -> 1 | D40: =D10 -> 0 | E40: =E10 -> 2 | F40: =F10 -> 0 | G40: =G10 -> 1 | H40: =SUM(B40:G40) -> 5 | J40: D | K40: 0.36 | L40: 0.16 | M40: 0.04 | N40: 0 | O40: 0.04 | P40: 0.16
A41: E | B41: =B11 -> 0 | C41: =C11 -> 0 | D41: =D11 -> 2 | E41: =E11 -> 1 | F41: =F11 -> 1 | G41: =G11 -> 1 | H41: =SUM(B41:G41) -> 5 | J41: E | K41: 0.64 | L41: 0.36 | M41: 0.16 | N41: 0.04 | O41: 0 | P41: 0.04
A42: F | B42: =B12 -> 0 | C42: =C12 -> 1 | D42: =D12 -> 0 | E42: =E12 -> 2 | F42: =F12 -> 0 | G42: =G12 -> 3 | H42: =SUM(B42:G42) -> 6 | J42: F | K42: 1 | L42: 0.64 | M42: 0.36 | N42: 0.16 | O42: 0.04 | P42: 0
A43: Total | B43: =SUM(B37:B42) -> 19 | C43: =SUM(C37:C42) -> 6 | D43: =SUM(D37:D42) -> 7 | E43: =SUM(E37:E42) -> 8 | F43: =SUM(F37:F42) -> 3 | G43: =SUM(G37:G42) -> 7 | H43: =SUM(B37:G42) -> 50
A45: Expected Matrix
C47: Judge 1
A48: Judge 2 | B48: A | C48: B | D48: C | E48: D | F48: E | G48: F | H48: Total | J48: Kappa | K48: =1-(M48/M49) -> 0.58745875 | L48: Num: | M48: =SUMPRODUCT(B37:G42,K37:P42) -> 5.4
A49: A | B49: =B$13*$H37/$H$13 -> 7.6 | C49: =C$13*$H37/$H$13 -> 2.4 | D49: =D$13*$H37/$H$13 -> 2.8 | E49: =E$13*$H37/$H$13 -> 3.2 | F49: =F$13*$H37/$H$13 -> 1.2 | G49: =G$13*$H37/$H$13 -> 2.8 | H49: =SUM(B49:G49) -> 20 | L49: Den: | M49: =SUMPRODUCT(B49:G54,K37:P42) -> 13.0896
A50: B | B50: =B$13*$H38/$H$13 -> 3.42 | C50: =C$13*$H38/$H$13 -> 1.08 | D50: =D$13*$H38/$H$13 -> 1.26 | E50: =E$13*$H38/$H$13 -> 1.44 | F50: =F$13*$H38/$H$13 -> 0.54 | G50: =G$13*$H38/$H$13 -> 1.26 | H50: =SUM(B50:G50) -> 9
A51: C | B51: =B$13*$H39/$H$13 -> 1.9 | C51: =C$13*$H39/$H$13 -> 0.6 | D51: =D$13*$H39/$H$13 -> 0.7 | E51: =E$13*$H39/$H$13 -> 0.8 | F51: =F$13*$H39/$H$13 -> 0.3 | G51: =G$13*$H39/$H$13 -> 0.7 | H51: =SUM(B51:G51) -> 5
A52: D | B52: =B$13*$H40/$H$13 -> 1.9 | C52: =C$13*$H40/$H$13 -> 0.6 | D52: =D$13*$H40/$H$13 -> 0.7 | E52: =E$13*$H40/$H$13 -> 0.8 | F52: =F$13*$H40/$H$13 -> 0.3 | G52: =G$13*$H40/$H$13 -> 0.7 | H52: =SUM(B52:G52) -> 5
A53: E | B53: =B$13*$H41/$H$13 -> 1.9 | C53: =C$13*$H41/$H$13 -> 0.6 | D53: =D$13*$H41/$H$13 -> 0.7 | E53: =E$13*$H41/$H$13 -> 0.8 | F53: =F$13*$H41/$H$13 -> 0.3 | G53: =G$13*$H41/$H$13 -> 0.7 | H53: =SUM(B53:G53) -> 5
...

Sheet WK_7class
A3: Confusion Matrix | T3: Confusion Matrix
K4: Weighted Kappa (Linear) | AD4: Unweighted Kappa (Cohen's Kappa)
C5: Judge 1 | M5: Weight | V5: Judge 1 | AF5: Weight
A6: Judge 2 | B6: A | C6: B | D6: C | E6: D | F6: E | G6: F | H6: G | I6: Total | L6: A | M6: B | N6: C | O6: D | P6: E | Q6: F | R6: G | T6: Judge 2 | U6: A | V6: B | W6: C | X6: D | Y6: E | Z6: F | AA6: G | AB6: Total | AE6: A | AF6: B | AG6: C | AH6: D | AI6: E | AJ6: F | AK6: G
A7: A | B7: 5 | C7: 2 | D7: 1 | E7: 1 | F7: 0 | G7: 1 | H7: 0 | I7: =SUM(B7:H7) -> 10 | K7: A | L7: 0 | M7: 1 | N7: 2 | O7: 3 | P7: 4 | Q7: 5 | R7: 6 | T7: A | U7: =B7 -> 5 | V7: =C7 -> 2 | W7: =D7 -> 1 | X7: =E7 -> 1 | Y7: =F7 -> 0 | Z7: =G7 -> 1 | AA7: =H7 -> 0 | AB7: =SUM(U7:AA7) -> 10 | AD7: A | AE7: 0 | AF7: 1 | AG7: 1 | AH7: 1 | AI7: 1 | AJ7: 1 | AK7: 1
A8: B | B8: 2 | C8: 4 | D8: 1 | E8: 2 | F8: 1 | G8: 0 | H8: 1 | I8: =SUM(B8:H8) -> 11 | K8: B | L8: 1 | M8: 0 | N8: 1 | O8: 2 | P8: 3 | Q8: 4 | R8: 5 | T8: B | U8: =B8 -> 2 | V8: =C8 -> 4 | W8: =D8 -> 1 | X8: =E8 -> 2 | Y8: =F8 -> 1 | Z8: =G8 -> 0 | AA8: =H8 -> 1 | AB8: =SUM(U8:AA8) -> 11 | AD8: B | AE8: 1 | AF8: 0 | AG8: 1 | AH8: 1 | AI8: 1 | AJ8: 1 | AK8: 1
